2023-07-02 23:15:58,327 jazzmin.templatetags.jazzmin WARNING  avatar field must be an ImageField/URLField on the user model, or a callable
2023-07-02 23:16:02,328 jazzmin.templatetags.jazzmin WARNING  avatar field must be an ImageField/URLField on the user model, or a callable
2023-07-03 01:13:21,662 django.request WARNING  Not Found: /
2023-07-03 01:15:21,720 django.request WARNING  Not Found: /api/docs
2023-07-03 01:15:21,841 django.request WARNING  Not Found: /favicon.ico
2023-07-03 01:15:25,868 django.request WARNING  Not Found: /api/docs/
2023-07-03 01:16:47,981 django.request WARNING  Not Found: /api/v5/docs/
2023-07-03 01:16:57,568 django.request WARNING  Not Found: /api/v5/
2023-07-03 01:17:17,070 django       ERROR    2 validation errors for NinjaResponseSchema
response -> message
  field required (type=value_error.missing)
response -> data
  field required (type=value_error.missing)
Traceback (most recent call last):
  File "/home/kayprogrammer/Documents/Projects/Django/bidout-auction-v5/env/lib/python3.11/site-packages/ninja/operation.py", line 266, in run
    return self._result_to_response(request, result, temporal_response)
           ^^^^^^^^^^^^^^^^^^^^^^^^^^^^^^^^^^^^^^^^^^^^^^^^^^^^^^^^^^^^
  File "/home/kayprogrammer/Documents/Projects/Django/bidout-auction-v5/env/lib/python3.11/site-packages/ninja/operation.py", line 202, in _result_to_response
    result = response_model.from_orm(resp_object).dict(
             ^^^^^^^^^^^^^^^^^^^^^^^^^^^^^^^^^^^^
  File "/home/kayprogrammer/Documents/Projects/Django/bidout-auction-v5/env/lib/python3.11/site-packages/ninja/schema.py", line 164, in from_orm
    return super().from_orm(obj)
           ^^^^^^^^^^^^^^^^^^^^^
  File "pydantic/main.py", line 579, in pydantic.main.BaseModel.from_orm
pydantic.error_wrappers.ValidationError: 2 validation errors for NinjaResponseSchema
response -> message
  field required (type=value_error.missing)
response -> data
  field required (type=value_error.missing)
2023-07-03 01:17:17,078 django.request ERROR    Internal Server Error: /api/v5/general/site-detail
2023-07-03 01:18:58,252 django.request WARNING  Not Found: /api/v5/general/site-detail/
2023-07-03 01:21:10,899 django.request WARNING  Not Found: /api/v5/general/site-detail/
2023-07-03 01:37:54,789 django.request WARNING  Not Found: /api/v5/docs
2023-07-03 01:37:54,867 django.request WARNING  Not Found: /favicon.ico
2023-07-03 01:38:01,550 django.request WARNING  Not Found: /
2023-07-03 01:38:13,590 django.request WARNING  Not Found: /
2023-07-03 02:58:21,427 django.request WARNING  Unprocessable Entity: /api/v5/general/subscribe/
2023-07-03 02:58:57,549 django.request WARNING  Unprocessable Entity: /api/v5/general/subscribe/
2023-07-03 02:59:24,379 django.request WARNING  Unprocessable Entity: /api/v5/general/subscribe/
2023-07-03 02:59:38,644 django.request WARNING  Unprocessable Entity: /api/v5/general/subscribe/
2023-07-03 03:06:01,799 django.request ERROR    Internal Server Error: /api/v5/general/subscribe/
Traceback (most recent call last):
  File "/home/kayprogrammer/Documents/Projects/Django/bidout-auction-v5/env/lib/python3.11/site-packages/ninja/operation.py", line 264, in run
    values = self._get_values(request, kw, temporal_response)
             ^^^^^^^^^^^^^^^^^^^^^^^^^^^^^^^^^^^^^^^^^^^^^^^^
  File "/home/kayprogrammer/Documents/Projects/Django/bidout-auction-v5/env/lib/python3.11/site-packages/ninja/operation.py", line 229, in _get_values
    raise ValidationError(errors)
ninja.errors.ValidationError

During handling of the above exception, another exception occurred:

Traceback (most recent call last):
  File "/home/kayprogrammer/Documents/Projects/Django/bidout-auction-v5/env/lib/python3.11/site-packages/asgiref/sync.py", line 534, in thread_handler
    raise exc_info[1]
  File "/home/kayprogrammer/Documents/Projects/Django/bidout-auction-v5/env/lib/python3.11/site-packages/django/core/handlers/exception.py", line 42, in inner
    response = await get_response(request)
               ^^^^^^^^^^^^^^^^^^^^^^^^^^^
  File "/home/kayprogrammer/Documents/Projects/Django/bidout-auction-v5/env/lib/python3.11/site-packages/asgiref/sync.py", line 534, in thread_handler
    raise exc_info[1]
  File "/home/kayprogrammer/Documents/Projects/Django/bidout-auction-v5/env/lib/python3.11/site-packages/django/core/handlers/base.py", line 253, in _get_response_async
    response = await wrapped_callback(
               ^^^^^^^^^^^^^^^^^^^^^^^
  File "/home/kayprogrammer/Documents/Projects/Django/bidout-auction-v5/env/lib/python3.11/site-packages/ninja/operation.py", line 390, in _async_view
    return await cast(AsyncOperation, operation).run(request, *a, **kw)
           ^^^^^^^^^^^^^^^^^^^^^^^^^^^^^^^^^^^^^^^^^^^^^^^^^^^^^^^^^^^^
  File "/home/kayprogrammer/Documents/Projects/Django/bidout-auction-v5/env/lib/python3.11/site-packages/ninja/operation.py", line 268, in run
    return self.api.on_exception(request, e)
           ^^^^^^^^^^^^^^^^^^^^^^^^^^^^^^^^^
  File "/home/kayprogrammer/Documents/Projects/Django/bidout-auction-v5/env/lib/python3.11/site-packages/ninja/main.py", line 471, in on_exception
    return handler(request, exc)
           ^^^^^^^^^^^^^^^^^^^^^
  File "/home/kayprogrammer/Documents/Projects/Django/bidout-auction-v5/apps/api.py", line 35, in validation_errors
    details = exc.extra
              ^^^^^^^^^
AttributeError: 'ValidationError' object has no attribute 'extra'
2023-07-03 03:06:21,797 django.request ERROR    Internal Server Error: /api/v5/general/subscribe/
Traceback (most recent call last):
  File "/home/kayprogrammer/Documents/Projects/Django/bidout-auction-v5/env/lib/python3.11/site-packages/ninja/operation.py", line 264, in run
    values = self._get_values(request, kw, temporal_response)
             ^^^^^^^^^^^^^^^^^^^^^^^^^^^^^^^^^^^^^^^^^^^^^^^^
  File "/home/kayprogrammer/Documents/Projects/Django/bidout-auction-v5/env/lib/python3.11/site-packages/ninja/operation.py", line 229, in _get_values
    raise ValidationError(errors)
ninja.errors.ValidationError

During handling of the above exception, another exception occurred:

Traceback (most recent call last):
  File "/home/kayprogrammer/Documents/Projects/Django/bidout-auction-v5/env/lib/python3.11/site-packages/asgiref/sync.py", line 534, in thread_handler
    raise exc_info[1]
  File "/home/kayprogrammer/Documents/Projects/Django/bidout-auction-v5/env/lib/python3.11/site-packages/django/core/handlers/exception.py", line 42, in inner
    response = await get_response(request)
               ^^^^^^^^^^^^^^^^^^^^^^^^^^^
  File "/home/kayprogrammer/Documents/Projects/Django/bidout-auction-v5/env/lib/python3.11/site-packages/asgiref/sync.py", line 534, in thread_handler
    raise exc_info[1]
  File "/home/kayprogrammer/Documents/Projects/Django/bidout-auction-v5/env/lib/python3.11/site-packages/django/core/handlers/base.py", line 253, in _get_response_async
    response = await wrapped_callback(
               ^^^^^^^^^^^^^^^^^^^^^^^
  File "/home/kayprogrammer/Documents/Projects/Django/bidout-auction-v5/env/lib/python3.11/site-packages/ninja/operation.py", line 390, in _async_view
    return await cast(AsyncOperation, operation).run(request, *a, **kw)
           ^^^^^^^^^^^^^^^^^^^^^^^^^^^^^^^^^^^^^^^^^^^^^^^^^^^^^^^^^^^^
  File "/home/kayprogrammer/Documents/Projects/Django/bidout-auction-v5/env/lib/python3.11/site-packages/ninja/operation.py", line 268, in run
    return self.api.on_exception(request, e)
           ^^^^^^^^^^^^^^^^^^^^^^^^^^^^^^^^^
  File "/home/kayprogrammer/Documents/Projects/Django/bidout-auction-v5/env/lib/python3.11/site-packages/ninja/main.py", line 471, in on_exception
    return handler(request, exc)
           ^^^^^^^^^^^^^^^^^^^^^
  File "/home/kayprogrammer/Documents/Projects/Django/bidout-auction-v5/apps/api.py", line 35, in validation_errors
    details = exc.detail
              ^^^^^^^^^^
AttributeError: 'ValidationError' object has no attribute 'detail'
2023-07-03 03:06:41,992 django.request ERROR    Internal Server Error: /api/v5/general/subscribe/
Traceback (most recent call last):
  File "/home/kayprogrammer/Documents/Projects/Django/bidout-auction-v5/env/lib/python3.11/site-packages/ninja/operation.py", line 264, in run
    values = self._get_values(request, kw, temporal_response)
             ^^^^^^^^^^^^^^^^^^^^^^^^^^^^^^^^^^^^^^^^^^^^^^^^
  File "/home/kayprogrammer/Documents/Projects/Django/bidout-auction-v5/env/lib/python3.11/site-packages/ninja/operation.py", line 229, in _get_values
    raise ValidationError(errors)
ninja.errors.ValidationError

During handling of the above exception, another exception occurred:

Traceback (most recent call last):
  File "/home/kayprogrammer/Documents/Projects/Django/bidout-auction-v5/env/lib/python3.11/site-packages/asgiref/sync.py", line 534, in thread_handler
    raise exc_info[1]
  File "/home/kayprogrammer/Documents/Projects/Django/bidout-auction-v5/env/lib/python3.11/site-packages/django/core/handlers/exception.py", line 42, in inner
    response = await get_response(request)
               ^^^^^^^^^^^^^^^^^^^^^^^^^^^
  File "/home/kayprogrammer/Documents/Projects/Django/bidout-auction-v5/env/lib/python3.11/site-packages/asgiref/sync.py", line 534, in thread_handler
    raise exc_info[1]
  File "/home/kayprogrammer/Documents/Projects/Django/bidout-auction-v5/env/lib/python3.11/site-packages/django/core/handlers/base.py", line 253, in _get_response_async
    response = await wrapped_callback(
               ^^^^^^^^^^^^^^^^^^^^^^^
  File "/home/kayprogrammer/Documents/Projects/Django/bidout-auction-v5/env/lib/python3.11/site-packages/ninja/operation.py", line 390, in _async_view
    return await cast(AsyncOperation, operation).run(request, *a, **kw)
           ^^^^^^^^^^^^^^^^^^^^^^^^^^^^^^^^^^^^^^^^^^^^^^^^^^^^^^^^^^^^
  File "/home/kayprogrammer/Documents/Projects/Django/bidout-auction-v5/env/lib/python3.11/site-packages/ninja/operation.py", line 268, in run
    return self.api.on_exception(request, e)
           ^^^^^^^^^^^^^^^^^^^^^^^^^^^^^^^^^
  File "/home/kayprogrammer/Documents/Projects/Django/bidout-auction-v5/env/lib/python3.11/site-packages/ninja/main.py", line 471, in on_exception
    return handler(request, exc)
           ^^^^^^^^^^^^^^^^^^^^^
  File "/home/kayprogrammer/Documents/Projects/Django/bidout-auction-v5/apps/api.py", line 35, in validation_errors
    details = exc.detail
              ^^^^^^^^^^
AttributeError: 'ValidationError' object has no attribute 'detail'
2023-07-03 03:07:07,621 django.request ERROR    Internal Server Error: /api/v5/general/subscribe/
Traceback (most recent call last):
  File "/home/kayprogrammer/Documents/Projects/Django/bidout-auction-v5/env/lib/python3.11/site-packages/ninja/operation.py", line 264, in run
    values = self._get_values(request, kw, temporal_response)
             ^^^^^^^^^^^^^^^^^^^^^^^^^^^^^^^^^^^^^^^^^^^^^^^^
  File "/home/kayprogrammer/Documents/Projects/Django/bidout-auction-v5/env/lib/python3.11/site-packages/ninja/operation.py", line 229, in _get_values
    raise ValidationError(errors)
ninja.errors.ValidationError

During handling of the above exception, another exception occurred:

Traceback (most recent call last):
  File "/home/kayprogrammer/Documents/Projects/Django/bidout-auction-v5/env/lib/python3.11/site-packages/asgiref/sync.py", line 534, in thread_handler
    raise exc_info[1]
  File "/home/kayprogrammer/Documents/Projects/Django/bidout-auction-v5/env/lib/python3.11/site-packages/django/core/handlers/exception.py", line 42, in inner
    response = await get_response(request)
               ^^^^^^^^^^^^^^^^^^^^^^^^^^^
  File "/home/kayprogrammer/Documents/Projects/Django/bidout-auction-v5/env/lib/python3.11/site-packages/asgiref/sync.py", line 534, in thread_handler
    raise exc_info[1]
  File "/home/kayprogrammer/Documents/Projects/Django/bidout-auction-v5/env/lib/python3.11/site-packages/django/core/handlers/base.py", line 253, in _get_response_async
    response = await wrapped_callback(
               ^^^^^^^^^^^^^^^^^^^^^^^
  File "/home/kayprogrammer/Documents/Projects/Django/bidout-auction-v5/env/lib/python3.11/site-packages/ninja/operation.py", line 390, in _async_view
    return await cast(AsyncOperation, operation).run(request, *a, **kw)
           ^^^^^^^^^^^^^^^^^^^^^^^^^^^^^^^^^^^^^^^^^^^^^^^^^^^^^^^^^^^^
  File "/home/kayprogrammer/Documents/Projects/Django/bidout-auction-v5/env/lib/python3.11/site-packages/ninja/operation.py", line 268, in run
    return self.api.on_exception(request, e)
           ^^^^^^^^^^^^^^^^^^^^^^^^^^^^^^^^^
  File "/home/kayprogrammer/Documents/Projects/Django/bidout-auction-v5/env/lib/python3.11/site-packages/ninja/main.py", line 471, in on_exception
    return handler(request, exc)
           ^^^^^^^^^^^^^^^^^^^^^
  File "/home/kayprogrammer/Documents/Projects/Django/bidout-auction-v5/apps/api.py", line 35, in validation_errors
    details = exc.detail
              ^^^^^^^^^^
AttributeError: 'ValidationError' object has no attribute 'detail'
2023-07-03 03:07:35,187 django.request ERROR    Internal Server Error: /api/v5/general/subscribe/
Traceback (most recent call last):
  File "/home/kayprogrammer/Documents/Projects/Django/bidout-auction-v5/env/lib/python3.11/site-packages/ninja/operation.py", line 264, in run
    values = self._get_values(request, kw, temporal_response)
             ^^^^^^^^^^^^^^^^^^^^^^^^^^^^^^^^^^^^^^^^^^^^^^^^
  File "/home/kayprogrammer/Documents/Projects/Django/bidout-auction-v5/env/lib/python3.11/site-packages/ninja/operation.py", line 229, in _get_values
    raise ValidationError(errors)
ninja.errors.ValidationError

During handling of the above exception, another exception occurred:

Traceback (most recent call last):
  File "/home/kayprogrammer/Documents/Projects/Django/bidout-auction-v5/env/lib/python3.11/site-packages/asgiref/sync.py", line 534, in thread_handler
    raise exc_info[1]
  File "/home/kayprogrammer/Documents/Projects/Django/bidout-auction-v5/env/lib/python3.11/site-packages/django/core/handlers/exception.py", line 42, in inner
    response = await get_response(request)
               ^^^^^^^^^^^^^^^^^^^^^^^^^^^
  File "/home/kayprogrammer/Documents/Projects/Django/bidout-auction-v5/env/lib/python3.11/site-packages/asgiref/sync.py", line 534, in thread_handler
    raise exc_info[1]
  File "/home/kayprogrammer/Documents/Projects/Django/bidout-auction-v5/env/lib/python3.11/site-packages/django/core/handlers/base.py", line 253, in _get_response_async
    response = await wrapped_callback(
               ^^^^^^^^^^^^^^^^^^^^^^^
  File "/home/kayprogrammer/Documents/Projects/Django/bidout-auction-v5/env/lib/python3.11/site-packages/ninja/operation.py", line 390, in _async_view
    return await cast(AsyncOperation, operation).run(request, *a, **kw)
           ^^^^^^^^^^^^^^^^^^^^^^^^^^^^^^^^^^^^^^^^^^^^^^^^^^^^^^^^^^^^
  File "/home/kayprogrammer/Documents/Projects/Django/bidout-auction-v5/env/lib/python3.11/site-packages/ninja/operation.py", line 268, in run
    return self.api.on_exception(request, e)
           ^^^^^^^^^^^^^^^^^^^^^^^^^^^^^^^^^
  File "/home/kayprogrammer/Documents/Projects/Django/bidout-auction-v5/env/lib/python3.11/site-packages/ninja/main.py", line 471, in on_exception
    return handler(request, exc)
           ^^^^^^^^^^^^^^^^^^^^^
  File "/home/kayprogrammer/Documents/Projects/Django/bidout-auction-v5/apps/api.py", line 35, in validation_errors
    for error in exc:
TypeError: 'ValidationError' object is not iterable
2023-07-03 03:07:53,166 django.request ERROR    Internal Server Error: /api/v5/general/subscribe/
Traceback (most recent call last):
  File "/home/kayprogrammer/Documents/Projects/Django/bidout-auction-v5/env/lib/python3.11/site-packages/ninja/operation.py", line 264, in run
    values = self._get_values(request, kw, temporal_response)
             ^^^^^^^^^^^^^^^^^^^^^^^^^^^^^^^^^^^^^^^^^^^^^^^^
  File "/home/kayprogrammer/Documents/Projects/Django/bidout-auction-v5/env/lib/python3.11/site-packages/ninja/operation.py", line 229, in _get_values
    raise ValidationError(errors)
ninja.errors.ValidationError

During handling of the above exception, another exception occurred:

Traceback (most recent call last):
  File "/home/kayprogrammer/Documents/Projects/Django/bidout-auction-v5/env/lib/python3.11/site-packages/asgiref/sync.py", line 534, in thread_handler
    raise exc_info[1]
  File "/home/kayprogrammer/Documents/Projects/Django/bidout-auction-v5/env/lib/python3.11/site-packages/django/core/handlers/exception.py", line 42, in inner
    response = await get_response(request)
               ^^^^^^^^^^^^^^^^^^^^^^^^^^^
  File "/home/kayprogrammer/Documents/Projects/Django/bidout-auction-v5/env/lib/python3.11/site-packages/asgiref/sync.py", line 534, in thread_handler
    raise exc_info[1]
  File "/home/kayprogrammer/Documents/Projects/Django/bidout-auction-v5/env/lib/python3.11/site-packages/django/core/handlers/base.py", line 253, in _get_response_async
    response = await wrapped_callback(
               ^^^^^^^^^^^^^^^^^^^^^^^
  File "/home/kayprogrammer/Documents/Projects/Django/bidout-auction-v5/env/lib/python3.11/site-packages/ninja/operation.py", line 390, in _async_view
    return await cast(AsyncOperation, operation).run(request, *a, **kw)
           ^^^^^^^^^^^^^^^^^^^^^^^^^^^^^^^^^^^^^^^^^^^^^^^^^^^^^^^^^^^^
  File "/home/kayprogrammer/Documents/Projects/Django/bidout-auction-v5/env/lib/python3.11/site-packages/ninja/operation.py", line 268, in run
    return self.api.on_exception(request, e)
           ^^^^^^^^^^^^^^^^^^^^^^^^^^^^^^^^^
  File "/home/kayprogrammer/Documents/Projects/Django/bidout-auction-v5/env/lib/python3.11/site-packages/ninja/main.py", line 471, in on_exception
    return handler(request, exc)
           ^^^^^^^^^^^^^^^^^^^^^
  File "/home/kayprogrammer/Documents/Projects/Django/bidout-auction-v5/apps/api.py", line 35, in validation_errors
    for error in dict(exc):
                 ^^^^^^^^^
TypeError: 'ValidationError' object is not iterable
2023-07-03 03:08:08,341 django.request ERROR    Internal Server Error: /api/v5/general/subscribe/
Traceback (most recent call last):
  File "/home/kayprogrammer/Documents/Projects/Django/bidout-auction-v5/env/lib/python3.11/site-packages/ninja/operation.py", line 264, in run
    values = self._get_values(request, kw, temporal_response)
             ^^^^^^^^^^^^^^^^^^^^^^^^^^^^^^^^^^^^^^^^^^^^^^^^
  File "/home/kayprogrammer/Documents/Projects/Django/bidout-auction-v5/env/lib/python3.11/site-packages/ninja/operation.py", line 229, in _get_values
    raise ValidationError(errors)
ninja.errors.ValidationError

During handling of the above exception, another exception occurred:

Traceback (most recent call last):
  File "/home/kayprogrammer/Documents/Projects/Django/bidout-auction-v5/env/lib/python3.11/site-packages/asgiref/sync.py", line 534, in thread_handler
    raise exc_info[1]
  File "/home/kayprogrammer/Documents/Projects/Django/bidout-auction-v5/env/lib/python3.11/site-packages/django/core/handlers/exception.py", line 42, in inner
    response = await get_response(request)
               ^^^^^^^^^^^^^^^^^^^^^^^^^^^
  File "/home/kayprogrammer/Documents/Projects/Django/bidout-auction-v5/env/lib/python3.11/site-packages/asgiref/sync.py", line 534, in thread_handler
    raise exc_info[1]
  File "/home/kayprogrammer/Documents/Projects/Django/bidout-auction-v5/env/lib/python3.11/site-packages/django/core/handlers/base.py", line 253, in _get_response_async
    response = await wrapped_callback(
               ^^^^^^^^^^^^^^^^^^^^^^^
  File "/home/kayprogrammer/Documents/Projects/Django/bidout-auction-v5/env/lib/python3.11/site-packages/ninja/operation.py", line 390, in _async_view
    return await cast(AsyncOperation, operation).run(request, *a, **kw)
           ^^^^^^^^^^^^^^^^^^^^^^^^^^^^^^^^^^^^^^^^^^^^^^^^^^^^^^^^^^^^
  File "/home/kayprogrammer/Documents/Projects/Django/bidout-auction-v5/env/lib/python3.11/site-packages/ninja/operation.py", line 268, in run
    return self.api.on_exception(request, e)
           ^^^^^^^^^^^^^^^^^^^^^^^^^^^^^^^^^
  File "/home/kayprogrammer/Documents/Projects/Django/bidout-auction-v5/env/lib/python3.11/site-packages/ninja/main.py", line 471, in on_exception
    return handler(request, exc)
           ^^^^^^^^^^^^^^^^^^^^^
  File "/home/kayprogrammer/Documents/Projects/Django/bidout-auction-v5/apps/api.py", line 35, in validation_errors
    for error in exc:
TypeError: 'ValidationError' object is not iterable
2023-07-03 03:08:40,875 django.request ERROR    Internal Server Error: /api/v5/general/subscribe/
Traceback (most recent call last):
  File "/home/kayprogrammer/Documents/Projects/Django/bidout-auction-v5/env/lib/python3.11/site-packages/ninja/operation.py", line 264, in run
    values = self._get_values(request, kw, temporal_response)
             ^^^^^^^^^^^^^^^^^^^^^^^^^^^^^^^^^^^^^^^^^^^^^^^^
  File "/home/kayprogrammer/Documents/Projects/Django/bidout-auction-v5/env/lib/python3.11/site-packages/ninja/operation.py", line 229, in _get_values
    raise ValidationError(errors)
ninja.errors.ValidationError

During handling of the above exception, another exception occurred:

Traceback (most recent call last):
  File "/home/kayprogrammer/Documents/Projects/Django/bidout-auction-v5/env/lib/python3.11/site-packages/asgiref/sync.py", line 534, in thread_handler
    raise exc_info[1]
  File "/home/kayprogrammer/Documents/Projects/Django/bidout-auction-v5/env/lib/python3.11/site-packages/django/core/handlers/exception.py", line 42, in inner
    response = await get_response(request)
               ^^^^^^^^^^^^^^^^^^^^^^^^^^^
  File "/home/kayprogrammer/Documents/Projects/Django/bidout-auction-v5/env/lib/python3.11/site-packages/asgiref/sync.py", line 534, in thread_handler
    raise exc_info[1]
  File "/home/kayprogrammer/Documents/Projects/Django/bidout-auction-v5/env/lib/python3.11/site-packages/django/core/handlers/base.py", line 253, in _get_response_async
    response = await wrapped_callback(
               ^^^^^^^^^^^^^^^^^^^^^^^
  File "/home/kayprogrammer/Documents/Projects/Django/bidout-auction-v5/env/lib/python3.11/site-packages/ninja/operation.py", line 390, in _async_view
    return await cast(AsyncOperation, operation).run(request, *a, **kw)
           ^^^^^^^^^^^^^^^^^^^^^^^^^^^^^^^^^^^^^^^^^^^^^^^^^^^^^^^^^^^^
  File "/home/kayprogrammer/Documents/Projects/Django/bidout-auction-v5/env/lib/python3.11/site-packages/ninja/operation.py", line 268, in run
    return self.api.on_exception(request, e)
           ^^^^^^^^^^^^^^^^^^^^^^^^^^^^^^^^^
  File "/home/kayprogrammer/Documents/Projects/Django/bidout-auction-v5/env/lib/python3.11/site-packages/ninja/main.py", line 471, in on_exception
    return handler(request, exc)
           ^^^^^^^^^^^^^^^^^^^^^
  File "/home/kayprogrammer/Documents/Projects/Django/bidout-auction-v5/apps/api.py", line 36, in validation_errors
    for error in exc:
TypeError: 'ValidationError' object is not iterable
2023-07-03 03:09:21,559 django.request WARNING  Unprocessable Entity: /api/v5/general/subscribe/
2023-07-03 03:09:23,494 django.request WARNING  Unprocessable Entity: /api/v5/general/subscribe/
2023-07-03 03:09:24,154 django.request WARNING  Unprocessable Entity: /api/v5/general/subscribe/
2023-07-03 03:12:27,754 django.request WARNING  Unprocessable Entity: /api/v5/general/subscribe/
2023-07-03 03:12:28,679 django.request WARNING  Unprocessable Entity: /api/v5/general/subscribe/
2023-07-03 03:12:29,381 django.request WARNING  Unprocessable Entity: /api/v5/general/subscribe/
2023-07-03 19:29:40,824 django       ERROR    apps.accounts.managers.CustomUserManager.create_user() argument after ** must be a mapping, not RegisterUserSchema
Traceback (most recent call last):
  File "/home/kayprogrammer/Documents/Projects/Django/bidout-auction-v5/env/lib/python3.11/site-packages/ninja/operation.py", line 265, in run
    result = await self.view_func(request, **values)
             ^^^^^^^^^^^^^^^^^^^^^^^^^^^^^^^^^^^^^^^
  File "/home/kayprogrammer/Documents/Projects/Django/bidout-auction-v5/apps/accounts/views.py", line 46, in register
    user = await User.objects.create_user(**data)
                 ^^^^^^^^^^^^^^^^^^^^^^^^^^^^^^^^
TypeError: apps.accounts.managers.CustomUserManager.create_user() argument after ** must be a mapping, not RegisterUserSchema
2023-07-03 19:29:40,979 django.request ERROR    Internal Server Error: /api/v5/auth/register/
2023-07-03 19:30:31,163 django       ERROR    unhashable type: 'RegisterUserSchema'
Traceback (most recent call last):
  File "/home/kayprogrammer/Documents/Projects/Django/bidout-auction-v5/env/lib/python3.11/site-packages/ninja/operation.py", line 265, in run
    result = await self.view_func(request, **values)
             ^^^^^^^^^^^^^^^^^^^^^^^^^^^^^^^^^^^^^^^
  File "/home/kayprogrammer/Documents/Projects/Django/bidout-auction-v5/apps/accounts/views.py", line 51, in register
    return {
           ^
TypeError: unhashable type: 'RegisterUserSchema'
2023-07-03 19:30:31,166 django.request ERROR    Internal Server Error: /api/v5/auth/register/
2023-07-03 19:31:02,633 django.request WARNING  Unprocessable Entity: /api/v5/auth/register/
2023-07-03 19:31:21,076 django       ERROR    unhashable type: 'RegisterUserSchema'
Traceback (most recent call last):
  File "/home/kayprogrammer/Documents/Projects/Django/bidout-auction-v5/env/lib/python3.11/site-packages/ninja/operation.py", line 265, in run
    result = await self.view_func(request, **values)
             ^^^^^^^^^^^^^^^^^^^^^^^^^^^^^^^^^^^^^^^
  File "/home/kayprogrammer/Documents/Projects/Django/bidout-auction-v5/apps/accounts/views.py", line 52, in register
    return {
           ^
TypeError: unhashable type: 'RegisterUserSchema'
2023-07-03 19:31:21,087 django.request ERROR    Internal Server Error: /api/v5/auth/register/
2023-07-03 20:46:29,596 django.request WARNING  Unauthorized: /api/v5/auth/logout/
2023-07-03 20:48:29,775 django.request ERROR    Internal Server Error: /api/v5/auth/logout/
Traceback (most recent call last):
  File "/home/kayprogrammer/Documents/Projects/Django/bidout-auction-v5/env/lib/python3.11/site-packages/asgiref/sync.py", line 534, in thread_handler
    raise exc_info[1]
  File "/home/kayprogrammer/Documents/Projects/Django/bidout-auction-v5/env/lib/python3.11/site-packages/django/core/handlers/exception.py", line 42, in inner
    response = await get_response(request)
               ^^^^^^^^^^^^^^^^^^^^^^^^^^^
  File "/home/kayprogrammer/Documents/Projects/Django/bidout-auction-v5/env/lib/python3.11/site-packages/django/utils/deprecation.py", line 152, in __acall__
    response = await sync_to_async(
               ^^^^^^^^^^^^^^^^^^^^
  File "/home/kayprogrammer/Documents/Projects/Django/bidout-auction-v5/env/lib/python3.11/site-packages/asgiref/sync.py", line 479, in __call__
    ret: _R = await loop.run_in_executor(
              ^^^^^^^^^^^^^^^^^^^^^^^^^^^
  File "/home/kayprogrammer/Documents/Projects/Django/bidout-auction-v5/env/lib/python3.11/site-packages/asgiref/current_thread_executor.py", line 40, in run
    result = self.fn(*self.args, **self.kwargs)
             ^^^^^^^^^^^^^^^^^^^^^^^^^^^^^^^^^^
  File "/home/kayprogrammer/Documents/Projects/Django/bidout-auction-v5/env/lib/python3.11/site-packages/asgiref/sync.py", line 538, in thread_handler
    return func(*args, **kwargs)
           ^^^^^^^^^^^^^^^^^^^^^
  File "/home/kayprogrammer/Documents/Projects/Django/bidout-auction-v5/env/lib/python3.11/site-packages/django/middleware/clickjacking.py", line 34, in process_response
    response.headers["X-Frame-Options"] = self.get_xframe_options_value(
    ^^^^^^^^^^^^^^^^
AttributeError: 'dict' object has no attribute 'headers'
2023-07-03 20:50:12,215 django.request ERROR    Internal Server Error: /api/v5/auth/logout/
Traceback (most recent call last):
  File "/home/kayprogrammer/Documents/Projects/Django/bidout-auction-v5/env/lib/python3.11/site-packages/asgiref/sync.py", line 534, in thread_handler
    raise exc_info[1]
  File "/home/kayprogrammer/Documents/Projects/Django/bidout-auction-v5/env/lib/python3.11/site-packages/django/core/handlers/exception.py", line 42, in inner
    response = await get_response(request)
               ^^^^^^^^^^^^^^^^^^^^^^^^^^^
  File "/home/kayprogrammer/Documents/Projects/Django/bidout-auction-v5/env/lib/python3.11/site-packages/asgiref/sync.py", line 534, in thread_handler
    raise exc_info[1]
  File "/home/kayprogrammer/Documents/Projects/Django/bidout-auction-v5/env/lib/python3.11/site-packages/django/core/handlers/base.py", line 253, in _get_response_async
    response = await wrapped_callback(
               ^^^^^^^^^^^^^^^^^^^^^^^
  File "/home/kayprogrammer/Documents/Projects/Django/bidout-auction-v5/env/lib/python3.11/site-packages/ninja/operation.py", line 390, in _async_view
    return await cast(AsyncOperation, operation).run(request, *a, **kw)
           ^^^^^^^^^^^^^^^^^^^^^^^^^^^^^^^^^^^^^^^^^^^^^^^^^^^^^^^^^^^^
  File "/home/kayprogrammer/Documents/Projects/Django/bidout-auction-v5/env/lib/python3.11/site-packages/ninja/operation.py", line 259, in run
    error = await self._run_checks(request)
            ^^^^^^^^^^^^^^^^^^^^^^^^^^^^^^^
  File "/home/kayprogrammer/Documents/Projects/Django/bidout-auction-v5/env/lib/python3.11/site-packages/ninja/operation.py", line 274, in _run_checks
    error = await self._run_authentication(request)
            ^^^^^^^^^^^^^^^^^^^^^^^^^^^^^^^^^^^^^^^
  File "/home/kayprogrammer/Documents/Projects/Django/bidout-auction-v5/env/lib/python3.11/site-packages/ninja/operation.py", line 299, in _run_authentication
    return self.api.on_exception(request, AuthenticationError())
           ^^^^^^^^^^^^^^^^^^^^^^^^^^^^^^^^^^^^^^^^^^^^^^^^^^^^^
  File "/home/kayprogrammer/Documents/Projects/Django/bidout-auction-v5/env/lib/python3.11/site-packages/ninja/main.py", line 471, in on_exception
    return handler(request, exc)
           ^^^^^^^^^^^^^^^^^^^^^
  File "/home/kayprogrammer/Documents/Projects/Django/bidout-auction-v5/apps/api.py", line 46, in request_exc_handler
    print(exc.detail)
          ^^^^^^^^^^
AttributeError: 'AuthenticationError' object has no attribute 'detail'
2023-07-03 20:50:24,170 django.request ERROR    Internal Server Error: /api/v5/auth/logout/
Traceback (most recent call last):
  File "/home/kayprogrammer/Documents/Projects/Django/bidout-auction-v5/env/lib/python3.11/site-packages/asgiref/sync.py", line 534, in thread_handler
    raise exc_info[1]
  File "/home/kayprogrammer/Documents/Projects/Django/bidout-auction-v5/env/lib/python3.11/site-packages/django/core/handlers/exception.py", line 42, in inner
    response = await get_response(request)
               ^^^^^^^^^^^^^^^^^^^^^^^^^^^
  File "/home/kayprogrammer/Documents/Projects/Django/bidout-auction-v5/env/lib/python3.11/site-packages/asgiref/sync.py", line 534, in thread_handler
    raise exc_info[1]
  File "/home/kayprogrammer/Documents/Projects/Django/bidout-auction-v5/env/lib/python3.11/site-packages/django/core/handlers/base.py", line 253, in _get_response_async
    response = await wrapped_callback(
               ^^^^^^^^^^^^^^^^^^^^^^^
  File "/home/kayprogrammer/Documents/Projects/Django/bidout-auction-v5/env/lib/python3.11/site-packages/ninja/operation.py", line 390, in _async_view
    return await cast(AsyncOperation, operation).run(request, *a, **kw)
           ^^^^^^^^^^^^^^^^^^^^^^^^^^^^^^^^^^^^^^^^^^^^^^^^^^^^^^^^^^^^
  File "/home/kayprogrammer/Documents/Projects/Django/bidout-auction-v5/env/lib/python3.11/site-packages/ninja/operation.py", line 259, in run
    error = await self._run_checks(request)
            ^^^^^^^^^^^^^^^^^^^^^^^^^^^^^^^
  File "/home/kayprogrammer/Documents/Projects/Django/bidout-auction-v5/env/lib/python3.11/site-packages/ninja/operation.py", line 274, in _run_checks
    error = await self._run_authentication(request)
            ^^^^^^^^^^^^^^^^^^^^^^^^^^^^^^^^^^^^^^^
  File "/home/kayprogrammer/Documents/Projects/Django/bidout-auction-v5/env/lib/python3.11/site-packages/ninja/operation.py", line 299, in _run_authentication
    return self.api.on_exception(request, AuthenticationError())
           ^^^^^^^^^^^^^^^^^^^^^^^^^^^^^^^^^^^^^^^^^^^^^^^^^^^^^
  File "/home/kayprogrammer/Documents/Projects/Django/bidout-auction-v5/env/lib/python3.11/site-packages/ninja/main.py", line 471, in on_exception
    return handler(request, exc)
           ^^^^^^^^^^^^^^^^^^^^^
  File "/home/kayprogrammer/Documents/Projects/Django/bidout-auction-v5/apps/api.py", line 46, in request_exc_handler
    print(exc.errors)
          ^^^^^^^^^^
AttributeError: 'AuthenticationError' object has no attribute 'errors'
2023-07-03 20:50:24,909 django.request ERROR    Internal Server Error: /api/v5/auth/logout/
Traceback (most recent call last):
  File "/home/kayprogrammer/Documents/Projects/Django/bidout-auction-v5/env/lib/python3.11/site-packages/asgiref/sync.py", line 534, in thread_handler
    raise exc_info[1]
  File "/home/kayprogrammer/Documents/Projects/Django/bidout-auction-v5/env/lib/python3.11/site-packages/django/core/handlers/exception.py", line 42, in inner
    response = await get_response(request)
               ^^^^^^^^^^^^^^^^^^^^^^^^^^^
  File "/home/kayprogrammer/Documents/Projects/Django/bidout-auction-v5/env/lib/python3.11/site-packages/asgiref/sync.py", line 534, in thread_handler
    raise exc_info[1]
  File "/home/kayprogrammer/Documents/Projects/Django/bidout-auction-v5/env/lib/python3.11/site-packages/django/core/handlers/base.py", line 253, in _get_response_async
    response = await wrapped_callback(
               ^^^^^^^^^^^^^^^^^^^^^^^
  File "/home/kayprogrammer/Documents/Projects/Django/bidout-auction-v5/env/lib/python3.11/site-packages/ninja/operation.py", line 390, in _async_view
    return await cast(AsyncOperation, operation).run(request, *a, **kw)
           ^^^^^^^^^^^^^^^^^^^^^^^^^^^^^^^^^^^^^^^^^^^^^^^^^^^^^^^^^^^^
  File "/home/kayprogrammer/Documents/Projects/Django/bidout-auction-v5/env/lib/python3.11/site-packages/ninja/operation.py", line 259, in run
    error = await self._run_checks(request)
            ^^^^^^^^^^^^^^^^^^^^^^^^^^^^^^^
  File "/home/kayprogrammer/Documents/Projects/Django/bidout-auction-v5/env/lib/python3.11/site-packages/ninja/operation.py", line 274, in _run_checks
    error = await self._run_authentication(request)
            ^^^^^^^^^^^^^^^^^^^^^^^^^^^^^^^^^^^^^^^
  File "/home/kayprogrammer/Documents/Projects/Django/bidout-auction-v5/env/lib/python3.11/site-packages/ninja/operation.py", line 299, in _run_authentication
    return self.api.on_exception(request, AuthenticationError())
           ^^^^^^^^^^^^^^^^^^^^^^^^^^^^^^^^^^^^^^^^^^^^^^^^^^^^^
  File "/home/kayprogrammer/Documents/Projects/Django/bidout-auction-v5/env/lib/python3.11/site-packages/ninja/main.py", line 471, in on_exception
    return handler(request, exc)
           ^^^^^^^^^^^^^^^^^^^^^
  File "/home/kayprogrammer/Documents/Projects/Django/bidout-auction-v5/apps/api.py", line 46, in request_exc_handler
    print(exc.errors)
          ^^^^^^^^^^
AttributeError: 'AuthenticationError' object has no attribute 'errors'
2023-07-03 20:53:12,401 django.request WARNING  Unauthorized: /api/v5/auth/logout/
2023-07-03 20:53:25,911 django.request WARNING  Unauthorized: /api/v5/auth/logout/
2023-07-03 20:54:01,320 django       ERROR    'coroutine' object has no attribute 'id'
Traceback (most recent call last):
  File "/home/kayprogrammer/Documents/Projects/Django/bidout-auction-v5/env/lib/python3.11/site-packages/ninja/operation.py", line 265, in run
    result = await self.view_func(request, **values)
             ^^^^^^^^^^^^^^^^^^^^^^^^^^^^^^^^^^^^^^^
  File "/home/kayprogrammer/Documents/Projects/Django/bidout-auction-v5/apps/accounts/views.py", line 248, in logout
    await Jwt.objects.filter(user_id=request.auth.id).adelete()
                                     ^^^^^^^^^^^^^^^
AttributeError: 'coroutine' object has no attribute 'id'
2023-07-03 20:54:01,324 django.request ERROR    Internal Server Error: /api/v5/auth/logout/
2023-07-03 20:54:42,879 django       ERROR    'coroutine' object has no attribute 'id'
Traceback (most recent call last):
  File "/home/kayprogrammer/Documents/Projects/Django/bidout-auction-v5/env/lib/python3.11/site-packages/ninja/operation.py", line 265, in run
    result = await self.view_func(request, **values)
             ^^^^^^^^^^^^^^^^^^^^^^^^^^^^^^^^^^^^^^^
  File "/home/kayprogrammer/Documents/Projects/Django/bidout-auction-v5/apps/accounts/views.py", line 248, in logout
    await Jwt.objects.filter(user_id=request.auth.id).adelete()
                                     ^^^^^^^^^^^^^^^
AttributeError: 'coroutine' object has no attribute 'id'
2023-07-03 20:54:42,881 django.request ERROR    Internal Server Error: /api/v5/auth/logout/
2023-07-03 20:55:14,156 django       ERROR    'coroutine' object has no attribute 'id'
Traceback (most recent call last):
  File "/home/kayprogrammer/Documents/Projects/Django/bidout-auction-v5/env/lib/python3.11/site-packages/ninja/operation.py", line 265, in run
    result = await self.view_func(request, **values)
             ^^^^^^^^^^^^^^^^^^^^^^^^^^^^^^^^^^^^^^^
  File "/home/kayprogrammer/Documents/Projects/Django/bidout-auction-v5/apps/accounts/views.py", line 249, in logout
    await Jwt.objects.filter(user_id=request.auth.id).adelete()
                                     ^^^^^^^^^^^^^^^
AttributeError: 'coroutine' object has no attribute 'id'
2023-07-03 20:55:14,161 django.request ERROR    Internal Server Error: /api/v5/auth/logout/
2023-07-03 20:56:41,758 django.request WARNING  Unauthorized: /api/v5/auth/logout/
2023-07-03 20:57:09,909 django       ERROR    'coroutine' object has no attribute 'id'
Traceback (most recent call last):
  File "/home/kayprogrammer/Documents/Projects/Django/bidout-auction-v5/env/lib/python3.11/site-packages/ninja/operation.py", line 265, in run
    result = await self.view_func(request, **values)
             ^^^^^^^^^^^^^^^^^^^^^^^^^^^^^^^^^^^^^^^
  File "/home/kayprogrammer/Documents/Projects/Django/bidout-auction-v5/apps/accounts/views.py", line 248, in logout
    await Jwt.objects.filter(user_id=(await request.auth.id)).adelete()
                                            ^^^^^^^^^^^^^^^
AttributeError: 'coroutine' object has no attribute 'id'
2023-07-03 20:57:09,912 django.request ERROR    Internal Server Error: /api/v5/auth/logout/
2023-07-03 20:57:24,753 django.request WARNING  Unauthorized: /api/v5/auth/logout/
2023-07-03 20:57:26,902 django.request WARNING  Unauthorized: /api/v5/auth/logout/
2023-07-03 20:57:27,693 django.request WARNING  Unauthorized: /api/v5/auth/logout/
2023-07-03 20:57:37,877 django.request WARNING  Unauthorized: /api/v5/auth/logout/
2023-07-03 21:01:20,646 django.request WARNING  Unauthorized: /api/v5/auth/login/
2023-07-03 21:01:27,998 django.request WARNING  Unauthorized: /api/v5/auth/login/
2023-07-03 21:01:31,684 django.request WARNING  Unauthorized: /api/v5/auth/login/
2023-07-03 21:06:17,913 django.request WARNING  Not Found: /api/v5/auth/resend-verification-email/
2023-07-03 21:07:11,028 django.request WARNING  Not Found: /api/v5/auth/verify-email/
2023-07-03 21:08:02,011 django.request WARNING  Not Found: /api/v5/auth/refresh/
2023-07-03 21:08:27,935 django.request WARNING  Unauthorized: /api/v5/auth/logout/
2023-07-03 21:08:31,429 django.request WARNING  Unauthorized: /api/v5/auth/logout/
2023-07-03 21:08:55,826 django.request WARNING  Unauthorized: /api/v5/auth/logout/
2023-07-03 21:09:29,530 django.request WARNING  Unauthorized: /api/v5/auth/logout/
2023-07-03 21:10:39,375 django.request WARNING  Unauthorized: /api/v5/auth/logout/
2023-07-03 21:11:44,992 django.request WARNING  Unauthorized: /api/v5/auth/logout/
2023-07-03 21:56:57,162 django.request WARNING  Unauthorized: /api/v5/general/site-detail/
2023-07-03 21:57:29,382 django       ERROR    ['“jsjsjs” is not a valid UUID.']
Traceback (most recent call last):
  File "/home/kayprogrammer/Documents/Projects/Django/bidout-auction-v5/env/lib/python3.11/site-packages/django/db/models/fields/__init__.py", line 2688, in to_python
    return uuid.UUID(**{input_form: value})
           ^^^^^^^^^^^^^^^^^^^^^^^^^^^^^^^^
  File "/usr/lib/python3.11/uuid.py", line 178, in __init__
    raise ValueError('badly formed hexadecimal UUID string')
ValueError: badly formed hexadecimal UUID string

During handling of the above exception, another exception occurred:

Traceback (most recent call last):
  File "/home/kayprogrammer/Documents/Projects/Django/bidout-auction-v5/env/lib/python3.11/site-packages/ninja/operation.py", line 265, in run
    result = await self.view_func(request, **values)
             ^^^^^^^^^^^^^^^^^^^^^^^^^^^^^^^^^^^^^^^
  File "/home/kayprogrammer/Documents/Projects/Django/bidout-auction-v5/apps/general/views.py", line 25, in retrieve_site_details
    print((await request.auth))
           ^^^^^^^^^^^^^^^^^^
  File "/home/kayprogrammer/Documents/Projects/Django/bidout-auction-v5/apps/common/utils.py", line 30, in authenticate
    guest = await GuestUser.objects.get_or_none(id=key)
            ^^^^^^^^^^^^^^^^^^^^^^^^^^^^^^^^^^^^^^^^^^^
  File "/home/kayprogrammer/Documents/Projects/Django/bidout-auction-v5/apps/common/managers.py", line 21, in get_or_none
    return await self.get_queryset().get_or_none(**kwargs)
           ^^^^^^^^^^^^^^^^^^^^^^^^^^^^^^^^^^^^^^^^^^^^^^^
  File "/home/kayprogrammer/Documents/Projects/Django/bidout-auction-v5/apps/common/managers.py", line 9, in get_or_none
    return await self.aget(**kwargs)
           ^^^^^^^^^^^^^^^^^^^^^^^^^
  File "/home/kayprogrammer/Documents/Projects/Django/bidout-auction-v5/env/lib/python3.11/site-packages/django/db/models/query.py", line 649, in aget
    return await sync_to_async(self.get)(*args, **kwargs)
           ^^^^^^^^^^^^^^^^^^^^^^^^^^^^^^^^^^^^^^^^^^^^^^
  File "/home/kayprogrammer/Documents/Projects/Django/bidout-auction-v5/env/lib/python3.11/site-packages/asgiref/sync.py", line 479, in __call__
    ret: _R = await loop.run_in_executor(
              ^^^^^^^^^^^^^^^^^^^^^^^^^^^
  File "/home/kayprogrammer/Documents/Projects/Django/bidout-auction-v5/env/lib/python3.11/site-packages/asgiref/current_thread_executor.py", line 40, in run
    result = self.fn(*self.args, **self.kwargs)
             ^^^^^^^^^^^^^^^^^^^^^^^^^^^^^^^^^^
  File "/home/kayprogrammer/Documents/Projects/Django/bidout-auction-v5/env/lib/python3.11/site-packages/asgiref/sync.py", line 538, in thread_handler
    return func(*args, **kwargs)
           ^^^^^^^^^^^^^^^^^^^^^
  File "/home/kayprogrammer/Documents/Projects/Django/bidout-auction-v5/env/lib/python3.11/site-packages/django/db/models/query.py", line 623, in get
    clone = self._chain() if self.query.combinator else self.filter(*args, **kwargs)
                                                        ^^^^^^^^^^^^^^^^^^^^^^^^^^^^
  File "/home/kayprogrammer/Documents/Projects/Django/bidout-auction-v5/env/lib/python3.11/site-packages/django/db/models/query.py", line 1436, in filter
    return self._filter_or_exclude(False, args, kwargs)
           ^^^^^^^^^^^^^^^^^^^^^^^^^^^^^^^^^^^^^^^^^^^^
  File "/home/kayprogrammer/Documents/Projects/Django/bidout-auction-v5/env/lib/python3.11/site-packages/django/db/models/query.py", line 1454, in _filter_or_exclude
    clone._filter_or_exclude_inplace(negate, args, kwargs)
  File "/home/kayprogrammer/Documents/Projects/Django/bidout-auction-v5/env/lib/python3.11/site-packages/django/db/models/query.py", line 1461, in _filter_or_exclude_inplace
    self._query.add_q(Q(*args, **kwargs))
  File "/home/kayprogrammer/Documents/Projects/Django/bidout-auction-v5/env/lib/python3.11/site-packages/django/db/models/sql/query.py", line 1534, in add_q
    clause, _ = self._add_q(q_object, self.used_aliases)
                ^^^^^^^^^^^^^^^^^^^^^^^^^^^^^^^^^^^^^^^^
  File "/home/kayprogrammer/Documents/Projects/Django/bidout-auction-v5/env/lib/python3.11/site-packages/django/db/models/sql/query.py", line 1565, in _add_q
    child_clause, needed_inner = self.build_filter(
                                 ^^^^^^^^^^^^^^^^^^
  File "/home/kayprogrammer/Documents/Projects/Django/bidout-auction-v5/env/lib/python3.11/site-packages/django/db/models/sql/query.py", line 1480, in build_filter
    condition = self.build_lookup(lookups, col, value)
                ^^^^^^^^^^^^^^^^^^^^^^^^^^^^^^^^^^^^^^
  File "/home/kayprogrammer/Documents/Projects/Django/bidout-auction-v5/env/lib/python3.11/site-packages/django/db/models/sql/query.py", line 1307, in build_lookup
    lookup = lookup_class(lhs, rhs)
             ^^^^^^^^^^^^^^^^^^^^^^
  File "/home/kayprogrammer/Documents/Projects/Django/bidout-auction-v5/env/lib/python3.11/site-packages/django/db/models/lookups.py", line 27, in __init__
    self.rhs = self.get_prep_lookup()
               ^^^^^^^^^^^^^^^^^^^^^^
  File "/home/kayprogrammer/Documents/Projects/Django/bidout-auction-v5/env/lib/python3.11/site-packages/django/db/models/lookups.py", line 341, in get_prep_lookup
    return super().get_prep_lookup()
           ^^^^^^^^^^^^^^^^^^^^^^^^^
  File "/home/kayprogrammer/Documents/Projects/Django/bidout-auction-v5/env/lib/python3.11/site-packages/django/db/models/lookups.py", line 85, in get_prep_lookup
    return self.lhs.output_field.get_prep_value(self.rhs)
           ^^^^^^^^^^^^^^^^^^^^^^^^^^^^^^^^^^^^^^^^^^^^^^
  File "/home/kayprogrammer/Documents/Projects/Django/bidout-auction-v5/env/lib/python3.11/site-packages/django/db/models/fields/__init__.py", line 2672, in get_prep_value
    return self.to_python(value)
           ^^^^^^^^^^^^^^^^^^^^^
  File "/home/kayprogrammer/Documents/Projects/Django/bidout-auction-v5/env/lib/python3.11/site-packages/django/db/models/fields/__init__.py", line 2690, in to_python
    raise exceptions.ValidationError(
django.core.exceptions.ValidationError: ['“jsjsjs” is not a valid UUID.']
2023-07-03 21:57:29,467 django.request ERROR    Internal Server Error: /api/v5/general/site-detail/
2023-07-03 22:01:13,422 django.request WARNING  Unauthorized: /api/v5/general/site-detail/
2023-07-03 22:21:11,500 django.request WARNING  Not Found: /api/v5/auth/set-new-password/
2023-07-03 22:21:48,258 django.request WARNING  Unauthorized: /api/v5/auth/login/
2023-07-03 22:21:51,656 django.request WARNING  Unauthorized: /api/v5/auth/login/
2023-07-03 22:21:58,922 django.request WARNING  Unauthorized: /api/v5/auth/login/
2023-07-03 22:32:53,880 django.request WARNING  Unauthorized: /api/v5/auth/login/
2023-07-03 22:33:09,766 django.request WARNING  Unauthorized: /api/v5/auth/login/
2023-07-03 22:33:30,836 django.request WARNING  Unauthorized: /api/v5/auth/login/
