2023-07-02 23:15:58,327 jazzmin.templatetags.jazzmin WARNING  avatar field must be an ImageField/URLField on the user model, or a callable
2023-07-02 23:16:02,328 jazzmin.templatetags.jazzmin WARNING  avatar field must be an ImageField/URLField on the user model, or a callable
2023-07-03 01:13:21,662 django.request WARNING  Not Found: /
2023-07-03 01:15:21,720 django.request WARNING  Not Found: /api/docs
2023-07-03 01:15:21,841 django.request WARNING  Not Found: /favicon.ico
2023-07-03 01:15:25,868 django.request WARNING  Not Found: /api/docs/
2023-07-03 01:16:47,981 django.request WARNING  Not Found: /api/v5/docs/
2023-07-03 01:16:57,568 django.request WARNING  Not Found: /api/v5/
2023-07-03 01:17:17,070 django       ERROR    2 validation errors for NinjaResponseSchema
response -> message
  field required (type=value_error.missing)
response -> data
  field required (type=value_error.missing)
Traceback (most recent call last):
  File "/home/kayprogrammer/Documents/Projects/Django/bidout-auction-v5/env/lib/python3.11/site-packages/ninja/operation.py", line 266, in run
    return self._result_to_response(request, result, temporal_response)
           ^^^^^^^^^^^^^^^^^^^^^^^^^^^^^^^^^^^^^^^^^^^^^^^^^^^^^^^^^^^^
  File "/home/kayprogrammer/Documents/Projects/Django/bidout-auction-v5/env/lib/python3.11/site-packages/ninja/operation.py", line 202, in _result_to_response
    result = response_model.from_orm(resp_object).dict(
             ^^^^^^^^^^^^^^^^^^^^^^^^^^^^^^^^^^^^
  File "/home/kayprogrammer/Documents/Projects/Django/bidout-auction-v5/env/lib/python3.11/site-packages/ninja/schema.py", line 164, in from_orm
    return super().from_orm(obj)
           ^^^^^^^^^^^^^^^^^^^^^
  File "pydantic/main.py", line 579, in pydantic.main.BaseModel.from_orm
pydantic.error_wrappers.ValidationError: 2 validation errors for NinjaResponseSchema
response -> message
  field required (type=value_error.missing)
response -> data
  field required (type=value_error.missing)
2023-07-03 01:17:17,078 django.request ERROR    Internal Server Error: /api/v5/general/site-detail
2023-07-03 01:18:58,252 django.request WARNING  Not Found: /api/v5/general/site-detail/
2023-07-03 01:21:10,899 django.request WARNING  Not Found: /api/v5/general/site-detail/
2023-07-03 01:37:54,789 django.request WARNING  Not Found: /api/v5/docs
2023-07-03 01:37:54,867 django.request WARNING  Not Found: /favicon.ico
2023-07-03 01:38:01,550 django.request WARNING  Not Found: /
2023-07-03 01:38:13,590 django.request WARNING  Not Found: /
2023-07-03 02:58:21,427 django.request WARNING  Unprocessable Entity: /api/v5/general/subscribe/
2023-07-03 02:58:57,549 django.request WARNING  Unprocessable Entity: /api/v5/general/subscribe/
2023-07-03 02:59:24,379 django.request WARNING  Unprocessable Entity: /api/v5/general/subscribe/
2023-07-03 02:59:38,644 django.request WARNING  Unprocessable Entity: /api/v5/general/subscribe/
2023-07-03 03:06:01,799 django.request ERROR    Internal Server Error: /api/v5/general/subscribe/
Traceback (most recent call last):
  File "/home/kayprogrammer/Documents/Projects/Django/bidout-auction-v5/env/lib/python3.11/site-packages/ninja/operation.py", line 264, in run
    values = self._get_values(request, kw, temporal_response)
             ^^^^^^^^^^^^^^^^^^^^^^^^^^^^^^^^^^^^^^^^^^^^^^^^
  File "/home/kayprogrammer/Documents/Projects/Django/bidout-auction-v5/env/lib/python3.11/site-packages/ninja/operation.py", line 229, in _get_values
    raise ValidationError(errors)
ninja.errors.ValidationError

During handling of the above exception, another exception occurred:

Traceback (most recent call last):
  File "/home/kayprogrammer/Documents/Projects/Django/bidout-auction-v5/env/lib/python3.11/site-packages/asgiref/sync.py", line 534, in thread_handler
    raise exc_info[1]
  File "/home/kayprogrammer/Documents/Projects/Django/bidout-auction-v5/env/lib/python3.11/site-packages/django/core/handlers/exception.py", line 42, in inner
    response = await get_response(request)
               ^^^^^^^^^^^^^^^^^^^^^^^^^^^
  File "/home/kayprogrammer/Documents/Projects/Django/bidout-auction-v5/env/lib/python3.11/site-packages/asgiref/sync.py", line 534, in thread_handler
    raise exc_info[1]
  File "/home/kayprogrammer/Documents/Projects/Django/bidout-auction-v5/env/lib/python3.11/site-packages/django/core/handlers/base.py", line 253, in _get_response_async
    response = await wrapped_callback(
               ^^^^^^^^^^^^^^^^^^^^^^^
  File "/home/kayprogrammer/Documents/Projects/Django/bidout-auction-v5/env/lib/python3.11/site-packages/ninja/operation.py", line 390, in _async_view
    return await cast(AsyncOperation, operation).run(request, *a, **kw)
           ^^^^^^^^^^^^^^^^^^^^^^^^^^^^^^^^^^^^^^^^^^^^^^^^^^^^^^^^^^^^
  File "/home/kayprogrammer/Documents/Projects/Django/bidout-auction-v5/env/lib/python3.11/site-packages/ninja/operation.py", line 268, in run
    return self.api.on_exception(request, e)
           ^^^^^^^^^^^^^^^^^^^^^^^^^^^^^^^^^
  File "/home/kayprogrammer/Documents/Projects/Django/bidout-auction-v5/env/lib/python3.11/site-packages/ninja/main.py", line 471, in on_exception
    return handler(request, exc)
           ^^^^^^^^^^^^^^^^^^^^^
  File "/home/kayprogrammer/Documents/Projects/Django/bidout-auction-v5/apps/api.py", line 35, in validation_errors
    details = exc.extra
              ^^^^^^^^^
AttributeError: 'ValidationError' object has no attribute 'extra'
2023-07-03 03:06:21,797 django.request ERROR    Internal Server Error: /api/v5/general/subscribe/
Traceback (most recent call last):
  File "/home/kayprogrammer/Documents/Projects/Django/bidout-auction-v5/env/lib/python3.11/site-packages/ninja/operation.py", line 264, in run
    values = self._get_values(request, kw, temporal_response)
             ^^^^^^^^^^^^^^^^^^^^^^^^^^^^^^^^^^^^^^^^^^^^^^^^
  File "/home/kayprogrammer/Documents/Projects/Django/bidout-auction-v5/env/lib/python3.11/site-packages/ninja/operation.py", line 229, in _get_values
    raise ValidationError(errors)
ninja.errors.ValidationError

During handling of the above exception, another exception occurred:

Traceback (most recent call last):
  File "/home/kayprogrammer/Documents/Projects/Django/bidout-auction-v5/env/lib/python3.11/site-packages/asgiref/sync.py", line 534, in thread_handler
    raise exc_info[1]
  File "/home/kayprogrammer/Documents/Projects/Django/bidout-auction-v5/env/lib/python3.11/site-packages/django/core/handlers/exception.py", line 42, in inner
    response = await get_response(request)
               ^^^^^^^^^^^^^^^^^^^^^^^^^^^
  File "/home/kayprogrammer/Documents/Projects/Django/bidout-auction-v5/env/lib/python3.11/site-packages/asgiref/sync.py", line 534, in thread_handler
    raise exc_info[1]
  File "/home/kayprogrammer/Documents/Projects/Django/bidout-auction-v5/env/lib/python3.11/site-packages/django/core/handlers/base.py", line 253, in _get_response_async
    response = await wrapped_callback(
               ^^^^^^^^^^^^^^^^^^^^^^^
  File "/home/kayprogrammer/Documents/Projects/Django/bidout-auction-v5/env/lib/python3.11/site-packages/ninja/operation.py", line 390, in _async_view
    return await cast(AsyncOperation, operation).run(request, *a, **kw)
           ^^^^^^^^^^^^^^^^^^^^^^^^^^^^^^^^^^^^^^^^^^^^^^^^^^^^^^^^^^^^
  File "/home/kayprogrammer/Documents/Projects/Django/bidout-auction-v5/env/lib/python3.11/site-packages/ninja/operation.py", line 268, in run
    return self.api.on_exception(request, e)
           ^^^^^^^^^^^^^^^^^^^^^^^^^^^^^^^^^
  File "/home/kayprogrammer/Documents/Projects/Django/bidout-auction-v5/env/lib/python3.11/site-packages/ninja/main.py", line 471, in on_exception
    return handler(request, exc)
           ^^^^^^^^^^^^^^^^^^^^^
  File "/home/kayprogrammer/Documents/Projects/Django/bidout-auction-v5/apps/api.py", line 35, in validation_errors
    details = exc.detail
              ^^^^^^^^^^
AttributeError: 'ValidationError' object has no attribute 'detail'
2023-07-03 03:06:41,992 django.request ERROR    Internal Server Error: /api/v5/general/subscribe/
Traceback (most recent call last):
  File "/home/kayprogrammer/Documents/Projects/Django/bidout-auction-v5/env/lib/python3.11/site-packages/ninja/operation.py", line 264, in run
    values = self._get_values(request, kw, temporal_response)
             ^^^^^^^^^^^^^^^^^^^^^^^^^^^^^^^^^^^^^^^^^^^^^^^^
  File "/home/kayprogrammer/Documents/Projects/Django/bidout-auction-v5/env/lib/python3.11/site-packages/ninja/operation.py", line 229, in _get_values
    raise ValidationError(errors)
ninja.errors.ValidationError

During handling of the above exception, another exception occurred:

Traceback (most recent call last):
  File "/home/kayprogrammer/Documents/Projects/Django/bidout-auction-v5/env/lib/python3.11/site-packages/asgiref/sync.py", line 534, in thread_handler
    raise exc_info[1]
  File "/home/kayprogrammer/Documents/Projects/Django/bidout-auction-v5/env/lib/python3.11/site-packages/django/core/handlers/exception.py", line 42, in inner
    response = await get_response(request)
               ^^^^^^^^^^^^^^^^^^^^^^^^^^^
  File "/home/kayprogrammer/Documents/Projects/Django/bidout-auction-v5/env/lib/python3.11/site-packages/asgiref/sync.py", line 534, in thread_handler
    raise exc_info[1]
  File "/home/kayprogrammer/Documents/Projects/Django/bidout-auction-v5/env/lib/python3.11/site-packages/django/core/handlers/base.py", line 253, in _get_response_async
    response = await wrapped_callback(
               ^^^^^^^^^^^^^^^^^^^^^^^
  File "/home/kayprogrammer/Documents/Projects/Django/bidout-auction-v5/env/lib/python3.11/site-packages/ninja/operation.py", line 390, in _async_view
    return await cast(AsyncOperation, operation).run(request, *a, **kw)
           ^^^^^^^^^^^^^^^^^^^^^^^^^^^^^^^^^^^^^^^^^^^^^^^^^^^^^^^^^^^^
  File "/home/kayprogrammer/Documents/Projects/Django/bidout-auction-v5/env/lib/python3.11/site-packages/ninja/operation.py", line 268, in run
    return self.api.on_exception(request, e)
           ^^^^^^^^^^^^^^^^^^^^^^^^^^^^^^^^^
  File "/home/kayprogrammer/Documents/Projects/Django/bidout-auction-v5/env/lib/python3.11/site-packages/ninja/main.py", line 471, in on_exception
    return handler(request, exc)
           ^^^^^^^^^^^^^^^^^^^^^
  File "/home/kayprogrammer/Documents/Projects/Django/bidout-auction-v5/apps/api.py", line 35, in validation_errors
    details = exc.detail
              ^^^^^^^^^^
AttributeError: 'ValidationError' object has no attribute 'detail'
2023-07-03 03:07:07,621 django.request ERROR    Internal Server Error: /api/v5/general/subscribe/
Traceback (most recent call last):
  File "/home/kayprogrammer/Documents/Projects/Django/bidout-auction-v5/env/lib/python3.11/site-packages/ninja/operation.py", line 264, in run
    values = self._get_values(request, kw, temporal_response)
             ^^^^^^^^^^^^^^^^^^^^^^^^^^^^^^^^^^^^^^^^^^^^^^^^
  File "/home/kayprogrammer/Documents/Projects/Django/bidout-auction-v5/env/lib/python3.11/site-packages/ninja/operation.py", line 229, in _get_values
    raise ValidationError(errors)
ninja.errors.ValidationError

During handling of the above exception, another exception occurred:

Traceback (most recent call last):
  File "/home/kayprogrammer/Documents/Projects/Django/bidout-auction-v5/env/lib/python3.11/site-packages/asgiref/sync.py", line 534, in thread_handler
    raise exc_info[1]
  File "/home/kayprogrammer/Documents/Projects/Django/bidout-auction-v5/env/lib/python3.11/site-packages/django/core/handlers/exception.py", line 42, in inner
    response = await get_response(request)
               ^^^^^^^^^^^^^^^^^^^^^^^^^^^
  File "/home/kayprogrammer/Documents/Projects/Django/bidout-auction-v5/env/lib/python3.11/site-packages/asgiref/sync.py", line 534, in thread_handler
    raise exc_info[1]
  File "/home/kayprogrammer/Documents/Projects/Django/bidout-auction-v5/env/lib/python3.11/site-packages/django/core/handlers/base.py", line 253, in _get_response_async
    response = await wrapped_callback(
               ^^^^^^^^^^^^^^^^^^^^^^^
  File "/home/kayprogrammer/Documents/Projects/Django/bidout-auction-v5/env/lib/python3.11/site-packages/ninja/operation.py", line 390, in _async_view
    return await cast(AsyncOperation, operation).run(request, *a, **kw)
           ^^^^^^^^^^^^^^^^^^^^^^^^^^^^^^^^^^^^^^^^^^^^^^^^^^^^^^^^^^^^
  File "/home/kayprogrammer/Documents/Projects/Django/bidout-auction-v5/env/lib/python3.11/site-packages/ninja/operation.py", line 268, in run
    return self.api.on_exception(request, e)
           ^^^^^^^^^^^^^^^^^^^^^^^^^^^^^^^^^
  File "/home/kayprogrammer/Documents/Projects/Django/bidout-auction-v5/env/lib/python3.11/site-packages/ninja/main.py", line 471, in on_exception
    return handler(request, exc)
           ^^^^^^^^^^^^^^^^^^^^^
  File "/home/kayprogrammer/Documents/Projects/Django/bidout-auction-v5/apps/api.py", line 35, in validation_errors
    details = exc.detail
              ^^^^^^^^^^
AttributeError: 'ValidationError' object has no attribute 'detail'
2023-07-03 03:07:35,187 django.request ERROR    Internal Server Error: /api/v5/general/subscribe/
Traceback (most recent call last):
  File "/home/kayprogrammer/Documents/Projects/Django/bidout-auction-v5/env/lib/python3.11/site-packages/ninja/operation.py", line 264, in run
    values = self._get_values(request, kw, temporal_response)
             ^^^^^^^^^^^^^^^^^^^^^^^^^^^^^^^^^^^^^^^^^^^^^^^^
  File "/home/kayprogrammer/Documents/Projects/Django/bidout-auction-v5/env/lib/python3.11/site-packages/ninja/operation.py", line 229, in _get_values
    raise ValidationError(errors)
ninja.errors.ValidationError

During handling of the above exception, another exception occurred:

Traceback (most recent call last):
  File "/home/kayprogrammer/Documents/Projects/Django/bidout-auction-v5/env/lib/python3.11/site-packages/asgiref/sync.py", line 534, in thread_handler
    raise exc_info[1]
  File "/home/kayprogrammer/Documents/Projects/Django/bidout-auction-v5/env/lib/python3.11/site-packages/django/core/handlers/exception.py", line 42, in inner
    response = await get_response(request)
               ^^^^^^^^^^^^^^^^^^^^^^^^^^^
  File "/home/kayprogrammer/Documents/Projects/Django/bidout-auction-v5/env/lib/python3.11/site-packages/asgiref/sync.py", line 534, in thread_handler
    raise exc_info[1]
  File "/home/kayprogrammer/Documents/Projects/Django/bidout-auction-v5/env/lib/python3.11/site-packages/django/core/handlers/base.py", line 253, in _get_response_async
    response = await wrapped_callback(
               ^^^^^^^^^^^^^^^^^^^^^^^
  File "/home/kayprogrammer/Documents/Projects/Django/bidout-auction-v5/env/lib/python3.11/site-packages/ninja/operation.py", line 390, in _async_view
    return await cast(AsyncOperation, operation).run(request, *a, **kw)
           ^^^^^^^^^^^^^^^^^^^^^^^^^^^^^^^^^^^^^^^^^^^^^^^^^^^^^^^^^^^^
  File "/home/kayprogrammer/Documents/Projects/Django/bidout-auction-v5/env/lib/python3.11/site-packages/ninja/operation.py", line 268, in run
    return self.api.on_exception(request, e)
           ^^^^^^^^^^^^^^^^^^^^^^^^^^^^^^^^^
  File "/home/kayprogrammer/Documents/Projects/Django/bidout-auction-v5/env/lib/python3.11/site-packages/ninja/main.py", line 471, in on_exception
    return handler(request, exc)
           ^^^^^^^^^^^^^^^^^^^^^
  File "/home/kayprogrammer/Documents/Projects/Django/bidout-auction-v5/apps/api.py", line 35, in validation_errors
    for error in exc:
TypeError: 'ValidationError' object is not iterable
2023-07-03 03:07:53,166 django.request ERROR    Internal Server Error: /api/v5/general/subscribe/
Traceback (most recent call last):
  File "/home/kayprogrammer/Documents/Projects/Django/bidout-auction-v5/env/lib/python3.11/site-packages/ninja/operation.py", line 264, in run
    values = self._get_values(request, kw, temporal_response)
             ^^^^^^^^^^^^^^^^^^^^^^^^^^^^^^^^^^^^^^^^^^^^^^^^
  File "/home/kayprogrammer/Documents/Projects/Django/bidout-auction-v5/env/lib/python3.11/site-packages/ninja/operation.py", line 229, in _get_values
    raise ValidationError(errors)
ninja.errors.ValidationError

During handling of the above exception, another exception occurred:

Traceback (most recent call last):
  File "/home/kayprogrammer/Documents/Projects/Django/bidout-auction-v5/env/lib/python3.11/site-packages/asgiref/sync.py", line 534, in thread_handler
    raise exc_info[1]
  File "/home/kayprogrammer/Documents/Projects/Django/bidout-auction-v5/env/lib/python3.11/site-packages/django/core/handlers/exception.py", line 42, in inner
    response = await get_response(request)
               ^^^^^^^^^^^^^^^^^^^^^^^^^^^
  File "/home/kayprogrammer/Documents/Projects/Django/bidout-auction-v5/env/lib/python3.11/site-packages/asgiref/sync.py", line 534, in thread_handler
    raise exc_info[1]
  File "/home/kayprogrammer/Documents/Projects/Django/bidout-auction-v5/env/lib/python3.11/site-packages/django/core/handlers/base.py", line 253, in _get_response_async
    response = await wrapped_callback(
               ^^^^^^^^^^^^^^^^^^^^^^^
  File "/home/kayprogrammer/Documents/Projects/Django/bidout-auction-v5/env/lib/python3.11/site-packages/ninja/operation.py", line 390, in _async_view
    return await cast(AsyncOperation, operation).run(request, *a, **kw)
           ^^^^^^^^^^^^^^^^^^^^^^^^^^^^^^^^^^^^^^^^^^^^^^^^^^^^^^^^^^^^
  File "/home/kayprogrammer/Documents/Projects/Django/bidout-auction-v5/env/lib/python3.11/site-packages/ninja/operation.py", line 268, in run
    return self.api.on_exception(request, e)
           ^^^^^^^^^^^^^^^^^^^^^^^^^^^^^^^^^
  File "/home/kayprogrammer/Documents/Projects/Django/bidout-auction-v5/env/lib/python3.11/site-packages/ninja/main.py", line 471, in on_exception
    return handler(request, exc)
           ^^^^^^^^^^^^^^^^^^^^^
  File "/home/kayprogrammer/Documents/Projects/Django/bidout-auction-v5/apps/api.py", line 35, in validation_errors
    for error in dict(exc):
                 ^^^^^^^^^
TypeError: 'ValidationError' object is not iterable
2023-07-03 03:08:08,341 django.request ERROR    Internal Server Error: /api/v5/general/subscribe/
Traceback (most recent call last):
  File "/home/kayprogrammer/Documents/Projects/Django/bidout-auction-v5/env/lib/python3.11/site-packages/ninja/operation.py", line 264, in run
    values = self._get_values(request, kw, temporal_response)
             ^^^^^^^^^^^^^^^^^^^^^^^^^^^^^^^^^^^^^^^^^^^^^^^^
  File "/home/kayprogrammer/Documents/Projects/Django/bidout-auction-v5/env/lib/python3.11/site-packages/ninja/operation.py", line 229, in _get_values
    raise ValidationError(errors)
ninja.errors.ValidationError

During handling of the above exception, another exception occurred:

Traceback (most recent call last):
  File "/home/kayprogrammer/Documents/Projects/Django/bidout-auction-v5/env/lib/python3.11/site-packages/asgiref/sync.py", line 534, in thread_handler
    raise exc_info[1]
  File "/home/kayprogrammer/Documents/Projects/Django/bidout-auction-v5/env/lib/python3.11/site-packages/django/core/handlers/exception.py", line 42, in inner
    response = await get_response(request)
               ^^^^^^^^^^^^^^^^^^^^^^^^^^^
  File "/home/kayprogrammer/Documents/Projects/Django/bidout-auction-v5/env/lib/python3.11/site-packages/asgiref/sync.py", line 534, in thread_handler
    raise exc_info[1]
  File "/home/kayprogrammer/Documents/Projects/Django/bidout-auction-v5/env/lib/python3.11/site-packages/django/core/handlers/base.py", line 253, in _get_response_async
    response = await wrapped_callback(
               ^^^^^^^^^^^^^^^^^^^^^^^
  File "/home/kayprogrammer/Documents/Projects/Django/bidout-auction-v5/env/lib/python3.11/site-packages/ninja/operation.py", line 390, in _async_view
    return await cast(AsyncOperation, operation).run(request, *a, **kw)
           ^^^^^^^^^^^^^^^^^^^^^^^^^^^^^^^^^^^^^^^^^^^^^^^^^^^^^^^^^^^^
  File "/home/kayprogrammer/Documents/Projects/Django/bidout-auction-v5/env/lib/python3.11/site-packages/ninja/operation.py", line 268, in run
    return self.api.on_exception(request, e)
           ^^^^^^^^^^^^^^^^^^^^^^^^^^^^^^^^^
  File "/home/kayprogrammer/Documents/Projects/Django/bidout-auction-v5/env/lib/python3.11/site-packages/ninja/main.py", line 471, in on_exception
    return handler(request, exc)
           ^^^^^^^^^^^^^^^^^^^^^
  File "/home/kayprogrammer/Documents/Projects/Django/bidout-auction-v5/apps/api.py", line 35, in validation_errors
    for error in exc:
TypeError: 'ValidationError' object is not iterable
2023-07-03 03:08:40,875 django.request ERROR    Internal Server Error: /api/v5/general/subscribe/
Traceback (most recent call last):
  File "/home/kayprogrammer/Documents/Projects/Django/bidout-auction-v5/env/lib/python3.11/site-packages/ninja/operation.py", line 264, in run
    values = self._get_values(request, kw, temporal_response)
             ^^^^^^^^^^^^^^^^^^^^^^^^^^^^^^^^^^^^^^^^^^^^^^^^
  File "/home/kayprogrammer/Documents/Projects/Django/bidout-auction-v5/env/lib/python3.11/site-packages/ninja/operation.py", line 229, in _get_values
    raise ValidationError(errors)
ninja.errors.ValidationError

During handling of the above exception, another exception occurred:

Traceback (most recent call last):
  File "/home/kayprogrammer/Documents/Projects/Django/bidout-auction-v5/env/lib/python3.11/site-packages/asgiref/sync.py", line 534, in thread_handler
    raise exc_info[1]
  File "/home/kayprogrammer/Documents/Projects/Django/bidout-auction-v5/env/lib/python3.11/site-packages/django/core/handlers/exception.py", line 42, in inner
    response = await get_response(request)
               ^^^^^^^^^^^^^^^^^^^^^^^^^^^
  File "/home/kayprogrammer/Documents/Projects/Django/bidout-auction-v5/env/lib/python3.11/site-packages/asgiref/sync.py", line 534, in thread_handler
    raise exc_info[1]
  File "/home/kayprogrammer/Documents/Projects/Django/bidout-auction-v5/env/lib/python3.11/site-packages/django/core/handlers/base.py", line 253, in _get_response_async
    response = await wrapped_callback(
               ^^^^^^^^^^^^^^^^^^^^^^^
  File "/home/kayprogrammer/Documents/Projects/Django/bidout-auction-v5/env/lib/python3.11/site-packages/ninja/operation.py", line 390, in _async_view
    return await cast(AsyncOperation, operation).run(request, *a, **kw)
           ^^^^^^^^^^^^^^^^^^^^^^^^^^^^^^^^^^^^^^^^^^^^^^^^^^^^^^^^^^^^
  File "/home/kayprogrammer/Documents/Projects/Django/bidout-auction-v5/env/lib/python3.11/site-packages/ninja/operation.py", line 268, in run
    return self.api.on_exception(request, e)
           ^^^^^^^^^^^^^^^^^^^^^^^^^^^^^^^^^
  File "/home/kayprogrammer/Documents/Projects/Django/bidout-auction-v5/env/lib/python3.11/site-packages/ninja/main.py", line 471, in on_exception
    return handler(request, exc)
           ^^^^^^^^^^^^^^^^^^^^^
  File "/home/kayprogrammer/Documents/Projects/Django/bidout-auction-v5/apps/api.py", line 36, in validation_errors
    for error in exc:
TypeError: 'ValidationError' object is not iterable
2023-07-03 03:09:21,559 django.request WARNING  Unprocessable Entity: /api/v5/general/subscribe/
2023-07-03 03:09:23,494 django.request WARNING  Unprocessable Entity: /api/v5/general/subscribe/
2023-07-03 03:09:24,154 django.request WARNING  Unprocessable Entity: /api/v5/general/subscribe/
2023-07-03 03:12:27,754 django.request WARNING  Unprocessable Entity: /api/v5/general/subscribe/
2023-07-03 03:12:28,679 django.request WARNING  Unprocessable Entity: /api/v5/general/subscribe/
2023-07-03 03:12:29,381 django.request WARNING  Unprocessable Entity: /api/v5/general/subscribe/
2023-07-03 19:29:40,824 django       ERROR    apps.accounts.managers.CustomUserManager.create_user() argument after ** must be a mapping, not RegisterUserSchema
Traceback (most recent call last):
  File "/home/kayprogrammer/Documents/Projects/Django/bidout-auction-v5/env/lib/python3.11/site-packages/ninja/operation.py", line 265, in run
    result = await self.view_func(request, **values)
             ^^^^^^^^^^^^^^^^^^^^^^^^^^^^^^^^^^^^^^^
  File "/home/kayprogrammer/Documents/Projects/Django/bidout-auction-v5/apps/accounts/views.py", line 46, in register
    user = await User.objects.create_user(**data)
                 ^^^^^^^^^^^^^^^^^^^^^^^^^^^^^^^^
TypeError: apps.accounts.managers.CustomUserManager.create_user() argument after ** must be a mapping, not RegisterUserSchema
2023-07-03 19:29:40,979 django.request ERROR    Internal Server Error: /api/v5/auth/register/
2023-07-03 19:30:31,163 django       ERROR    unhashable type: 'RegisterUserSchema'
Traceback (most recent call last):
  File "/home/kayprogrammer/Documents/Projects/Django/bidout-auction-v5/env/lib/python3.11/site-packages/ninja/operation.py", line 265, in run
    result = await self.view_func(request, **values)
             ^^^^^^^^^^^^^^^^^^^^^^^^^^^^^^^^^^^^^^^
  File "/home/kayprogrammer/Documents/Projects/Django/bidout-auction-v5/apps/accounts/views.py", line 51, in register
    return {
           ^
TypeError: unhashable type: 'RegisterUserSchema'
2023-07-03 19:30:31,166 django.request ERROR    Internal Server Error: /api/v5/auth/register/
2023-07-03 19:31:02,633 django.request WARNING  Unprocessable Entity: /api/v5/auth/register/
2023-07-03 19:31:21,076 django       ERROR    unhashable type: 'RegisterUserSchema'
Traceback (most recent call last):
  File "/home/kayprogrammer/Documents/Projects/Django/bidout-auction-v5/env/lib/python3.11/site-packages/ninja/operation.py", line 265, in run
    result = await self.view_func(request, **values)
             ^^^^^^^^^^^^^^^^^^^^^^^^^^^^^^^^^^^^^^^
  File "/home/kayprogrammer/Documents/Projects/Django/bidout-auction-v5/apps/accounts/views.py", line 52, in register
    return {
           ^
TypeError: unhashable type: 'RegisterUserSchema'
2023-07-03 19:31:21,087 django.request ERROR    Internal Server Error: /api/v5/auth/register/
2023-07-03 20:46:29,596 django.request WARNING  Unauthorized: /api/v5/auth/logout/
2023-07-03 20:48:29,775 django.request ERROR    Internal Server Error: /api/v5/auth/logout/
Traceback (most recent call last):
  File "/home/kayprogrammer/Documents/Projects/Django/bidout-auction-v5/env/lib/python3.11/site-packages/asgiref/sync.py", line 534, in thread_handler
    raise exc_info[1]
  File "/home/kayprogrammer/Documents/Projects/Django/bidout-auction-v5/env/lib/python3.11/site-packages/django/core/handlers/exception.py", line 42, in inner
    response = await get_response(request)
               ^^^^^^^^^^^^^^^^^^^^^^^^^^^
  File "/home/kayprogrammer/Documents/Projects/Django/bidout-auction-v5/env/lib/python3.11/site-packages/django/utils/deprecation.py", line 152, in __acall__
    response = await sync_to_async(
               ^^^^^^^^^^^^^^^^^^^^
  File "/home/kayprogrammer/Documents/Projects/Django/bidout-auction-v5/env/lib/python3.11/site-packages/asgiref/sync.py", line 479, in __call__
    ret: _R = await loop.run_in_executor(
              ^^^^^^^^^^^^^^^^^^^^^^^^^^^
  File "/home/kayprogrammer/Documents/Projects/Django/bidout-auction-v5/env/lib/python3.11/site-packages/asgiref/current_thread_executor.py", line 40, in run
    result = self.fn(*self.args, **self.kwargs)
             ^^^^^^^^^^^^^^^^^^^^^^^^^^^^^^^^^^
  File "/home/kayprogrammer/Documents/Projects/Django/bidout-auction-v5/env/lib/python3.11/site-packages/asgiref/sync.py", line 538, in thread_handler
    return func(*args, **kwargs)
           ^^^^^^^^^^^^^^^^^^^^^
  File "/home/kayprogrammer/Documents/Projects/Django/bidout-auction-v5/env/lib/python3.11/site-packages/django/middleware/clickjacking.py", line 34, in process_response
    response.headers["X-Frame-Options"] = self.get_xframe_options_value(
    ^^^^^^^^^^^^^^^^
AttributeError: 'dict' object has no attribute 'headers'
2023-07-03 20:50:12,215 django.request ERROR    Internal Server Error: /api/v5/auth/logout/
Traceback (most recent call last):
  File "/home/kayprogrammer/Documents/Projects/Django/bidout-auction-v5/env/lib/python3.11/site-packages/asgiref/sync.py", line 534, in thread_handler
    raise exc_info[1]
  File "/home/kayprogrammer/Documents/Projects/Django/bidout-auction-v5/env/lib/python3.11/site-packages/django/core/handlers/exception.py", line 42, in inner
    response = await get_response(request)
               ^^^^^^^^^^^^^^^^^^^^^^^^^^^
  File "/home/kayprogrammer/Documents/Projects/Django/bidout-auction-v5/env/lib/python3.11/site-packages/asgiref/sync.py", line 534, in thread_handler
    raise exc_info[1]
  File "/home/kayprogrammer/Documents/Projects/Django/bidout-auction-v5/env/lib/python3.11/site-packages/django/core/handlers/base.py", line 253, in _get_response_async
    response = await wrapped_callback(
               ^^^^^^^^^^^^^^^^^^^^^^^
  File "/home/kayprogrammer/Documents/Projects/Django/bidout-auction-v5/env/lib/python3.11/site-packages/ninja/operation.py", line 390, in _async_view
    return await cast(AsyncOperation, operation).run(request, *a, **kw)
           ^^^^^^^^^^^^^^^^^^^^^^^^^^^^^^^^^^^^^^^^^^^^^^^^^^^^^^^^^^^^
  File "/home/kayprogrammer/Documents/Projects/Django/bidout-auction-v5/env/lib/python3.11/site-packages/ninja/operation.py", line 259, in run
    error = await self._run_checks(request)
            ^^^^^^^^^^^^^^^^^^^^^^^^^^^^^^^
  File "/home/kayprogrammer/Documents/Projects/Django/bidout-auction-v5/env/lib/python3.11/site-packages/ninja/operation.py", line 274, in _run_checks
    error = await self._run_authentication(request)
            ^^^^^^^^^^^^^^^^^^^^^^^^^^^^^^^^^^^^^^^
  File "/home/kayprogrammer/Documents/Projects/Django/bidout-auction-v5/env/lib/python3.11/site-packages/ninja/operation.py", line 299, in _run_authentication
    return self.api.on_exception(request, AuthenticationError())
           ^^^^^^^^^^^^^^^^^^^^^^^^^^^^^^^^^^^^^^^^^^^^^^^^^^^^^
  File "/home/kayprogrammer/Documents/Projects/Django/bidout-auction-v5/env/lib/python3.11/site-packages/ninja/main.py", line 471, in on_exception
    return handler(request, exc)
           ^^^^^^^^^^^^^^^^^^^^^
  File "/home/kayprogrammer/Documents/Projects/Django/bidout-auction-v5/apps/api.py", line 46, in request_exc_handler
    print(exc.detail)
          ^^^^^^^^^^
AttributeError: 'AuthenticationError' object has no attribute 'detail'
2023-07-03 20:50:24,170 django.request ERROR    Internal Server Error: /api/v5/auth/logout/
Traceback (most recent call last):
  File "/home/kayprogrammer/Documents/Projects/Django/bidout-auction-v5/env/lib/python3.11/site-packages/asgiref/sync.py", line 534, in thread_handler
    raise exc_info[1]
  File "/home/kayprogrammer/Documents/Projects/Django/bidout-auction-v5/env/lib/python3.11/site-packages/django/core/handlers/exception.py", line 42, in inner
    response = await get_response(request)
               ^^^^^^^^^^^^^^^^^^^^^^^^^^^
  File "/home/kayprogrammer/Documents/Projects/Django/bidout-auction-v5/env/lib/python3.11/site-packages/asgiref/sync.py", line 534, in thread_handler
    raise exc_info[1]
  File "/home/kayprogrammer/Documents/Projects/Django/bidout-auction-v5/env/lib/python3.11/site-packages/django/core/handlers/base.py", line 253, in _get_response_async
    response = await wrapped_callback(
               ^^^^^^^^^^^^^^^^^^^^^^^
  File "/home/kayprogrammer/Documents/Projects/Django/bidout-auction-v5/env/lib/python3.11/site-packages/ninja/operation.py", line 390, in _async_view
    return await cast(AsyncOperation, operation).run(request, *a, **kw)
           ^^^^^^^^^^^^^^^^^^^^^^^^^^^^^^^^^^^^^^^^^^^^^^^^^^^^^^^^^^^^
  File "/home/kayprogrammer/Documents/Projects/Django/bidout-auction-v5/env/lib/python3.11/site-packages/ninja/operation.py", line 259, in run
    error = await self._run_checks(request)
            ^^^^^^^^^^^^^^^^^^^^^^^^^^^^^^^
  File "/home/kayprogrammer/Documents/Projects/Django/bidout-auction-v5/env/lib/python3.11/site-packages/ninja/operation.py", line 274, in _run_checks
    error = await self._run_authentication(request)
            ^^^^^^^^^^^^^^^^^^^^^^^^^^^^^^^^^^^^^^^
  File "/home/kayprogrammer/Documents/Projects/Django/bidout-auction-v5/env/lib/python3.11/site-packages/ninja/operation.py", line 299, in _run_authentication
    return self.api.on_exception(request, AuthenticationError())
           ^^^^^^^^^^^^^^^^^^^^^^^^^^^^^^^^^^^^^^^^^^^^^^^^^^^^^
  File "/home/kayprogrammer/Documents/Projects/Django/bidout-auction-v5/env/lib/python3.11/site-packages/ninja/main.py", line 471, in on_exception
    return handler(request, exc)
           ^^^^^^^^^^^^^^^^^^^^^
  File "/home/kayprogrammer/Documents/Projects/Django/bidout-auction-v5/apps/api.py", line 46, in request_exc_handler
    print(exc.errors)
          ^^^^^^^^^^
AttributeError: 'AuthenticationError' object has no attribute 'errors'
2023-07-03 20:50:24,909 django.request ERROR    Internal Server Error: /api/v5/auth/logout/
Traceback (most recent call last):
  File "/home/kayprogrammer/Documents/Projects/Django/bidout-auction-v5/env/lib/python3.11/site-packages/asgiref/sync.py", line 534, in thread_handler
    raise exc_info[1]
  File "/home/kayprogrammer/Documents/Projects/Django/bidout-auction-v5/env/lib/python3.11/site-packages/django/core/handlers/exception.py", line 42, in inner
    response = await get_response(request)
               ^^^^^^^^^^^^^^^^^^^^^^^^^^^
  File "/home/kayprogrammer/Documents/Projects/Django/bidout-auction-v5/env/lib/python3.11/site-packages/asgiref/sync.py", line 534, in thread_handler
    raise exc_info[1]
  File "/home/kayprogrammer/Documents/Projects/Django/bidout-auction-v5/env/lib/python3.11/site-packages/django/core/handlers/base.py", line 253, in _get_response_async
    response = await wrapped_callback(
               ^^^^^^^^^^^^^^^^^^^^^^^
  File "/home/kayprogrammer/Documents/Projects/Django/bidout-auction-v5/env/lib/python3.11/site-packages/ninja/operation.py", line 390, in _async_view
    return await cast(AsyncOperation, operation).run(request, *a, **kw)
           ^^^^^^^^^^^^^^^^^^^^^^^^^^^^^^^^^^^^^^^^^^^^^^^^^^^^^^^^^^^^
  File "/home/kayprogrammer/Documents/Projects/Django/bidout-auction-v5/env/lib/python3.11/site-packages/ninja/operation.py", line 259, in run
    error = await self._run_checks(request)
            ^^^^^^^^^^^^^^^^^^^^^^^^^^^^^^^
  File "/home/kayprogrammer/Documents/Projects/Django/bidout-auction-v5/env/lib/python3.11/site-packages/ninja/operation.py", line 274, in _run_checks
    error = await self._run_authentication(request)
            ^^^^^^^^^^^^^^^^^^^^^^^^^^^^^^^^^^^^^^^
  File "/home/kayprogrammer/Documents/Projects/Django/bidout-auction-v5/env/lib/python3.11/site-packages/ninja/operation.py", line 299, in _run_authentication
    return self.api.on_exception(request, AuthenticationError())
           ^^^^^^^^^^^^^^^^^^^^^^^^^^^^^^^^^^^^^^^^^^^^^^^^^^^^^
  File "/home/kayprogrammer/Documents/Projects/Django/bidout-auction-v5/env/lib/python3.11/site-packages/ninja/main.py", line 471, in on_exception
    return handler(request, exc)
           ^^^^^^^^^^^^^^^^^^^^^
  File "/home/kayprogrammer/Documents/Projects/Django/bidout-auction-v5/apps/api.py", line 46, in request_exc_handler
    print(exc.errors)
          ^^^^^^^^^^
AttributeError: 'AuthenticationError' object has no attribute 'errors'
2023-07-03 20:53:12,401 django.request WARNING  Unauthorized: /api/v5/auth/logout/
2023-07-03 20:53:25,911 django.request WARNING  Unauthorized: /api/v5/auth/logout/
2023-07-03 20:54:01,320 django       ERROR    'coroutine' object has no attribute 'id'
Traceback (most recent call last):
  File "/home/kayprogrammer/Documents/Projects/Django/bidout-auction-v5/env/lib/python3.11/site-packages/ninja/operation.py", line 265, in run
    result = await self.view_func(request, **values)
             ^^^^^^^^^^^^^^^^^^^^^^^^^^^^^^^^^^^^^^^
  File "/home/kayprogrammer/Documents/Projects/Django/bidout-auction-v5/apps/accounts/views.py", line 248, in logout
    await Jwt.objects.filter(user_id=request.auth.id).adelete()
                                     ^^^^^^^^^^^^^^^
AttributeError: 'coroutine' object has no attribute 'id'
2023-07-03 20:54:01,324 django.request ERROR    Internal Server Error: /api/v5/auth/logout/
2023-07-03 20:54:42,879 django       ERROR    'coroutine' object has no attribute 'id'
Traceback (most recent call last):
  File "/home/kayprogrammer/Documents/Projects/Django/bidout-auction-v5/env/lib/python3.11/site-packages/ninja/operation.py", line 265, in run
    result = await self.view_func(request, **values)
             ^^^^^^^^^^^^^^^^^^^^^^^^^^^^^^^^^^^^^^^
  File "/home/kayprogrammer/Documents/Projects/Django/bidout-auction-v5/apps/accounts/views.py", line 248, in logout
    await Jwt.objects.filter(user_id=request.auth.id).adelete()
                                     ^^^^^^^^^^^^^^^
AttributeError: 'coroutine' object has no attribute 'id'
2023-07-03 20:54:42,881 django.request ERROR    Internal Server Error: /api/v5/auth/logout/
2023-07-03 20:55:14,156 django       ERROR    'coroutine' object has no attribute 'id'
Traceback (most recent call last):
  File "/home/kayprogrammer/Documents/Projects/Django/bidout-auction-v5/env/lib/python3.11/site-packages/ninja/operation.py", line 265, in run
    result = await self.view_func(request, **values)
             ^^^^^^^^^^^^^^^^^^^^^^^^^^^^^^^^^^^^^^^
  File "/home/kayprogrammer/Documents/Projects/Django/bidout-auction-v5/apps/accounts/views.py", line 249, in logout
    await Jwt.objects.filter(user_id=request.auth.id).adelete()
                                     ^^^^^^^^^^^^^^^
AttributeError: 'coroutine' object has no attribute 'id'
2023-07-03 20:55:14,161 django.request ERROR    Internal Server Error: /api/v5/auth/logout/
2023-07-03 20:56:41,758 django.request WARNING  Unauthorized: /api/v5/auth/logout/
2023-07-03 20:57:09,909 django       ERROR    'coroutine' object has no attribute 'id'
Traceback (most recent call last):
  File "/home/kayprogrammer/Documents/Projects/Django/bidout-auction-v5/env/lib/python3.11/site-packages/ninja/operation.py", line 265, in run
    result = await self.view_func(request, **values)
             ^^^^^^^^^^^^^^^^^^^^^^^^^^^^^^^^^^^^^^^
  File "/home/kayprogrammer/Documents/Projects/Django/bidout-auction-v5/apps/accounts/views.py", line 248, in logout
    await Jwt.objects.filter(user_id=(await request.auth.id)).adelete()
                                            ^^^^^^^^^^^^^^^
AttributeError: 'coroutine' object has no attribute 'id'
2023-07-03 20:57:09,912 django.request ERROR    Internal Server Error: /api/v5/auth/logout/
2023-07-03 20:57:24,753 django.request WARNING  Unauthorized: /api/v5/auth/logout/
2023-07-03 20:57:26,902 django.request WARNING  Unauthorized: /api/v5/auth/logout/
2023-07-03 20:57:27,693 django.request WARNING  Unauthorized: /api/v5/auth/logout/
2023-07-03 20:57:37,877 django.request WARNING  Unauthorized: /api/v5/auth/logout/
2023-07-03 21:01:20,646 django.request WARNING  Unauthorized: /api/v5/auth/login/
2023-07-03 21:01:27,998 django.request WARNING  Unauthorized: /api/v5/auth/login/
2023-07-03 21:01:31,684 django.request WARNING  Unauthorized: /api/v5/auth/login/
2023-07-03 21:06:17,913 django.request WARNING  Not Found: /api/v5/auth/resend-verification-email/
2023-07-03 21:07:11,028 django.request WARNING  Not Found: /api/v5/auth/verify-email/
2023-07-03 21:08:02,011 django.request WARNING  Not Found: /api/v5/auth/refresh/
2023-07-03 21:08:27,935 django.request WARNING  Unauthorized: /api/v5/auth/logout/
2023-07-03 21:08:31,429 django.request WARNING  Unauthorized: /api/v5/auth/logout/
2023-07-03 21:08:55,826 django.request WARNING  Unauthorized: /api/v5/auth/logout/
2023-07-03 21:09:29,530 django.request WARNING  Unauthorized: /api/v5/auth/logout/
2023-07-03 21:10:39,375 django.request WARNING  Unauthorized: /api/v5/auth/logout/
2023-07-03 21:11:44,992 django.request WARNING  Unauthorized: /api/v5/auth/logout/
2023-07-03 21:56:57,162 django.request WARNING  Unauthorized: /api/v5/general/site-detail/
2023-07-03 21:57:29,382 django       ERROR    ['“jsjsjs” is not a valid UUID.']
Traceback (most recent call last):
  File "/home/kayprogrammer/Documents/Projects/Django/bidout-auction-v5/env/lib/python3.11/site-packages/django/db/models/fields/__init__.py", line 2688, in to_python
    return uuid.UUID(**{input_form: value})
           ^^^^^^^^^^^^^^^^^^^^^^^^^^^^^^^^
  File "/usr/lib/python3.11/uuid.py", line 178, in __init__
    raise ValueError('badly formed hexadecimal UUID string')
ValueError: badly formed hexadecimal UUID string

During handling of the above exception, another exception occurred:

Traceback (most recent call last):
  File "/home/kayprogrammer/Documents/Projects/Django/bidout-auction-v5/env/lib/python3.11/site-packages/ninja/operation.py", line 265, in run
    result = await self.view_func(request, **values)
             ^^^^^^^^^^^^^^^^^^^^^^^^^^^^^^^^^^^^^^^
  File "/home/kayprogrammer/Documents/Projects/Django/bidout-auction-v5/apps/general/views.py", line 25, in retrieve_site_details
    print((await request.auth))
           ^^^^^^^^^^^^^^^^^^
  File "/home/kayprogrammer/Documents/Projects/Django/bidout-auction-v5/apps/common/utils.py", line 30, in authenticate
    guest = await GuestUser.objects.get_or_none(id=key)
            ^^^^^^^^^^^^^^^^^^^^^^^^^^^^^^^^^^^^^^^^^^^
  File "/home/kayprogrammer/Documents/Projects/Django/bidout-auction-v5/apps/common/managers.py", line 21, in get_or_none
    return await self.get_queryset().get_or_none(**kwargs)
           ^^^^^^^^^^^^^^^^^^^^^^^^^^^^^^^^^^^^^^^^^^^^^^^
  File "/home/kayprogrammer/Documents/Projects/Django/bidout-auction-v5/apps/common/managers.py", line 9, in get_or_none
    return await self.aget(**kwargs)
           ^^^^^^^^^^^^^^^^^^^^^^^^^
  File "/home/kayprogrammer/Documents/Projects/Django/bidout-auction-v5/env/lib/python3.11/site-packages/django/db/models/query.py", line 649, in aget
    return await sync_to_async(self.get)(*args, **kwargs)
           ^^^^^^^^^^^^^^^^^^^^^^^^^^^^^^^^^^^^^^^^^^^^^^
  File "/home/kayprogrammer/Documents/Projects/Django/bidout-auction-v5/env/lib/python3.11/site-packages/asgiref/sync.py", line 479, in __call__
    ret: _R = await loop.run_in_executor(
              ^^^^^^^^^^^^^^^^^^^^^^^^^^^
  File "/home/kayprogrammer/Documents/Projects/Django/bidout-auction-v5/env/lib/python3.11/site-packages/asgiref/current_thread_executor.py", line 40, in run
    result = self.fn(*self.args, **self.kwargs)
             ^^^^^^^^^^^^^^^^^^^^^^^^^^^^^^^^^^
  File "/home/kayprogrammer/Documents/Projects/Django/bidout-auction-v5/env/lib/python3.11/site-packages/asgiref/sync.py", line 538, in thread_handler
    return func(*args, **kwargs)
           ^^^^^^^^^^^^^^^^^^^^^
  File "/home/kayprogrammer/Documents/Projects/Django/bidout-auction-v5/env/lib/python3.11/site-packages/django/db/models/query.py", line 623, in get
    clone = self._chain() if self.query.combinator else self.filter(*args, **kwargs)
                                                        ^^^^^^^^^^^^^^^^^^^^^^^^^^^^
  File "/home/kayprogrammer/Documents/Projects/Django/bidout-auction-v5/env/lib/python3.11/site-packages/django/db/models/query.py", line 1436, in filter
    return self._filter_or_exclude(False, args, kwargs)
           ^^^^^^^^^^^^^^^^^^^^^^^^^^^^^^^^^^^^^^^^^^^^
  File "/home/kayprogrammer/Documents/Projects/Django/bidout-auction-v5/env/lib/python3.11/site-packages/django/db/models/query.py", line 1454, in _filter_or_exclude
    clone._filter_or_exclude_inplace(negate, args, kwargs)
  File "/home/kayprogrammer/Documents/Projects/Django/bidout-auction-v5/env/lib/python3.11/site-packages/django/db/models/query.py", line 1461, in _filter_or_exclude_inplace
    self._query.add_q(Q(*args, **kwargs))
  File "/home/kayprogrammer/Documents/Projects/Django/bidout-auction-v5/env/lib/python3.11/site-packages/django/db/models/sql/query.py", line 1534, in add_q
    clause, _ = self._add_q(q_object, self.used_aliases)
                ^^^^^^^^^^^^^^^^^^^^^^^^^^^^^^^^^^^^^^^^
  File "/home/kayprogrammer/Documents/Projects/Django/bidout-auction-v5/env/lib/python3.11/site-packages/django/db/models/sql/query.py", line 1565, in _add_q
    child_clause, needed_inner = self.build_filter(
                                 ^^^^^^^^^^^^^^^^^^
  File "/home/kayprogrammer/Documents/Projects/Django/bidout-auction-v5/env/lib/python3.11/site-packages/django/db/models/sql/query.py", line 1480, in build_filter
    condition = self.build_lookup(lookups, col, value)
                ^^^^^^^^^^^^^^^^^^^^^^^^^^^^^^^^^^^^^^
  File "/home/kayprogrammer/Documents/Projects/Django/bidout-auction-v5/env/lib/python3.11/site-packages/django/db/models/sql/query.py", line 1307, in build_lookup
    lookup = lookup_class(lhs, rhs)
             ^^^^^^^^^^^^^^^^^^^^^^
  File "/home/kayprogrammer/Documents/Projects/Django/bidout-auction-v5/env/lib/python3.11/site-packages/django/db/models/lookups.py", line 27, in __init__
    self.rhs = self.get_prep_lookup()
               ^^^^^^^^^^^^^^^^^^^^^^
  File "/home/kayprogrammer/Documents/Projects/Django/bidout-auction-v5/env/lib/python3.11/site-packages/django/db/models/lookups.py", line 341, in get_prep_lookup
    return super().get_prep_lookup()
           ^^^^^^^^^^^^^^^^^^^^^^^^^
  File "/home/kayprogrammer/Documents/Projects/Django/bidout-auction-v5/env/lib/python3.11/site-packages/django/db/models/lookups.py", line 85, in get_prep_lookup
    return self.lhs.output_field.get_prep_value(self.rhs)
           ^^^^^^^^^^^^^^^^^^^^^^^^^^^^^^^^^^^^^^^^^^^^^^
  File "/home/kayprogrammer/Documents/Projects/Django/bidout-auction-v5/env/lib/python3.11/site-packages/django/db/models/fields/__init__.py", line 2672, in get_prep_value
    return self.to_python(value)
           ^^^^^^^^^^^^^^^^^^^^^
  File "/home/kayprogrammer/Documents/Projects/Django/bidout-auction-v5/env/lib/python3.11/site-packages/django/db/models/fields/__init__.py", line 2690, in to_python
    raise exceptions.ValidationError(
django.core.exceptions.ValidationError: ['“jsjsjs” is not a valid UUID.']
2023-07-03 21:57:29,467 django.request ERROR    Internal Server Error: /api/v5/general/site-detail/
2023-07-03 22:01:13,422 django.request WARNING  Unauthorized: /api/v5/general/site-detail/
2023-07-03 22:21:11,500 django.request WARNING  Not Found: /api/v5/auth/set-new-password/
2023-07-03 22:21:48,258 django.request WARNING  Unauthorized: /api/v5/auth/login/
2023-07-03 22:21:51,656 django.request WARNING  Unauthorized: /api/v5/auth/login/
2023-07-03 22:21:58,922 django.request WARNING  Unauthorized: /api/v5/auth/login/
2023-07-03 22:32:53,880 django.request WARNING  Unauthorized: /api/v5/auth/login/
2023-07-03 22:33:09,766 django.request WARNING  Unauthorized: /api/v5/auth/login/
2023-07-03 22:33:30,836 django.request WARNING  Unauthorized: /api/v5/auth/login/
2023-07-03 22:44:51,868 django.request WARNING  Bad Request: /api/v5/general/subscribe/
2023-07-03 22:47:58,765 django.request WARNING  Bad Request: /api/v5/general/subscribe/
2023-07-03 22:57:03,003 django.request WARNING  Bad Request: /api/v5/general/subscribe/
2023-07-03 22:59:10,787 django.request WARNING  Bad Request: /api/v5/general/subscribe/
2023-07-03 23:11:17,781 django.request ERROR    Internal Server Error: /api/v5/general/reviews/
Traceback (most recent call last):
  File "/home/kayprogrammer/Documents/Projects/Django/bidout-auction-v5/env/lib/python3.11/site-packages/django/core/handlers/exception.py", line 55, in inner
    response = get_response(request)
               ^^^^^^^^^^^^^^^^^^^^^
  File "/home/kayprogrammer/Documents/Projects/Django/bidout-auction-v5/env/lib/python3.11/site-packages/django/core/handlers/base.py", line 197, in _get_response
    response = wrapped_callback(request, *callback_args, **callback_kwargs)
               ^^^^^^^^^^^^^^^^^^^^^^^^^^^^^^^^^^^^^^^^^^^^^^^^^^^^^^^^^^^^
  File "/home/kayprogrammer/Documents/Projects/Django/bidout-auction-v5/env/lib/python3.11/site-packages/asgiref/sync.py", line 209, in __call__
    raise RuntimeError(
RuntimeError: You cannot use AsyncToSync in the same thread as an async event loop - just await the async function directly.
2023-07-04 10:31:05,314 django.request WARNING  Bad Request: /api/v5/general/subscribe/
2023-07-04 10:33:12,972 django.request WARNING  Bad Request: /api/v5/general/subscribe/
2023-07-04 10:33:58,108 django.request WARNING  Bad Request: /api/v5/general/subscribe/
2023-07-04 10:38:50,242 django.request WARNING  Bad Request: /api/v5/general/subscribe/
2023-07-04 10:51:49,710 django.request WARNING  Not Found: /api/v5/auth/send-password-reset-otp/
2023-07-04 10:51:50,434 django.request WARNING  Unauthorized: /api/v5/auth/login/
2023-07-04 10:51:50,796 django.request WARNING  Unauthorized: /api/v5/auth/login/
2023-07-04 11:03:00,258 django       ERROR    You cannot call this from an async context - use a thread or sync_to_async.
Traceback (most recent call last):
  File "/home/kayprogrammer/Documents/Projects/Django/bidout-auction-v5/env/lib/python3.11/site-packages/ninja/operation.py", line 292, in _run_authentication
    result = callback(request)
             ^^^^^^^^^^^^^^^^^
  File "/home/kayprogrammer/Documents/Projects/Django/bidout-auction-v5/env/lib/python3.11/site-packages/ninja/security/apikey.py", line 22, in __call__
    return self.authenticate(request, key)
           ^^^^^^^^^^^^^^^^^^^^^^^^^^^^^^^
  File "/home/kayprogrammer/Documents/Projects/Django/bidout-auction-v5/apps/common/utils.py", line 30, in authenticate
    guest = GuestUser.objects.filter(id=is_uuid(key)).first()
            ^^^^^^^^^^^^^^^^^^^^^^^^^^^^^^^^^^^^^^^^^^^^^^^^^
  File "/home/kayprogrammer/Documents/Projects/Django/bidout-auction-v5/env/lib/python3.11/site-packages/django/db/models/query.py", line 1057, in first
    for obj in queryset[:1]:
  File "/home/kayprogrammer/Documents/Projects/Django/bidout-auction-v5/env/lib/python3.11/site-packages/django/db/models/query.py", line 398, in __iter__
    self._fetch_all()
  File "/home/kayprogrammer/Documents/Projects/Django/bidout-auction-v5/env/lib/python3.11/site-packages/django/db/models/query.py", line 1881, in _fetch_all
    self._result_cache = list(self._iterable_class(self))
                         ^^^^^^^^^^^^^^^^^^^^^^^^^^^^^^^^
  File "/home/kayprogrammer/Documents/Projects/Django/bidout-auction-v5/env/lib/python3.11/site-packages/django/db/models/query.py", line 91, in __iter__
    results = compiler.execute_sql(
              ^^^^^^^^^^^^^^^^^^^^^
  File "/home/kayprogrammer/Documents/Projects/Django/bidout-auction-v5/env/lib/python3.11/site-packages/django/db/models/sql/compiler.py", line 1560, in execute_sql
    cursor = self.connection.cursor()
             ^^^^^^^^^^^^^^^^^^^^^^^^
  File "/home/kayprogrammer/Documents/Projects/Django/bidout-auction-v5/env/lib/python3.11/site-packages/django/utils/asyncio.py", line 24, in inner
    raise SynchronousOnlyOperation(message)
django.core.exceptions.SynchronousOnlyOperation: You cannot call this from an async context - use a thread or sync_to_async.
2023-07-04 11:03:00,288 django.request ERROR    Internal Server Error: /api/v5/auth/login/
2023-07-04 11:03:50,703 django       ERROR    You cannot call this from an async context - use a thread or sync_to_async.
Traceback (most recent call last):
  File "/home/kayprogrammer/Documents/Projects/Django/bidout-auction-v5/env/lib/python3.11/site-packages/ninja/operation.py", line 292, in _run_authentication
    result = callback(request)
             ^^^^^^^^^^^^^^^^^
  File "/home/kayprogrammer/Documents/Projects/Django/bidout-auction-v5/env/lib/python3.11/site-packages/ninja/security/apikey.py", line 22, in __call__
    return self.authenticate(request, key)
           ^^^^^^^^^^^^^^^^^^^^^^^^^^^^^^^
  File "/home/kayprogrammer/Documents/Projects/Django/bidout-auction-v5/apps/common/utils.py", line 30, in authenticate
    guest = GuestUser.objects.filter(id=is_uuid(key)).first()
            ^^^^^^^^^^^^^^^^^^^^^^^^^^^^^^^^^^^^^^^^^^^^^^^^^
  File "/home/kayprogrammer/Documents/Projects/Django/bidout-auction-v5/env/lib/python3.11/site-packages/django/db/models/query.py", line 1057, in first
    for obj in queryset[:1]:
  File "/home/kayprogrammer/Documents/Projects/Django/bidout-auction-v5/env/lib/python3.11/site-packages/django/db/models/query.py", line 398, in __iter__
    self._fetch_all()
  File "/home/kayprogrammer/Documents/Projects/Django/bidout-auction-v5/env/lib/python3.11/site-packages/django/db/models/query.py", line 1881, in _fetch_all
    self._result_cache = list(self._iterable_class(self))
                         ^^^^^^^^^^^^^^^^^^^^^^^^^^^^^^^^
  File "/home/kayprogrammer/Documents/Projects/Django/bidout-auction-v5/env/lib/python3.11/site-packages/django/db/models/query.py", line 91, in __iter__
    results = compiler.execute_sql(
              ^^^^^^^^^^^^^^^^^^^^^
  File "/home/kayprogrammer/Documents/Projects/Django/bidout-auction-v5/env/lib/python3.11/site-packages/django/db/models/sql/compiler.py", line 1560, in execute_sql
    cursor = self.connection.cursor()
             ^^^^^^^^^^^^^^^^^^^^^^^^
  File "/home/kayprogrammer/Documents/Projects/Django/bidout-auction-v5/env/lib/python3.11/site-packages/django/utils/asyncio.py", line 24, in inner
    raise SynchronousOnlyOperation(message)
django.core.exceptions.SynchronousOnlyOperation: You cannot call this from an async context - use a thread or sync_to_async.
2023-07-04 11:03:50,710 django.request ERROR    Internal Server Error: /api/v5/auth/login/
2023-07-04 11:04:35,624 django.request WARNING  Unauthorized: /api/v5/auth/login/
2023-07-04 11:04:52,379 django       ERROR    You cannot call this from an async context - use a thread or sync_to_async.
Traceback (most recent call last):
  File "/home/kayprogrammer/Documents/Projects/Django/bidout-auction-v5/env/lib/python3.11/site-packages/ninja/operation.py", line 292, in _run_authentication
    result = callback(request)
             ^^^^^^^^^^^^^^^^^
  File "/home/kayprogrammer/Documents/Projects/Django/bidout-auction-v5/env/lib/python3.11/site-packages/ninja/security/apikey.py", line 22, in __call__
    return self.authenticate(request, key)
           ^^^^^^^^^^^^^^^^^^^^^^^^^^^^^^^
  File "/home/kayprogrammer/Documents/Projects/Django/bidout-auction-v5/apps/common/utils.py", line 30, in authenticate
    guest = GuestUser.objects.filter(id=is_uuid(key)).first()
            ^^^^^^^^^^^^^^^^^^^^^^^^^^^^^^^^^^^^^^^^^^^^^^^^^
  File "/home/kayprogrammer/Documents/Projects/Django/bidout-auction-v5/env/lib/python3.11/site-packages/django/db/models/query.py", line 1057, in first
    for obj in queryset[:1]:
  File "/home/kayprogrammer/Documents/Projects/Django/bidout-auction-v5/env/lib/python3.11/site-packages/django/db/models/query.py", line 398, in __iter__
    self._fetch_all()
  File "/home/kayprogrammer/Documents/Projects/Django/bidout-auction-v5/env/lib/python3.11/site-packages/django/db/models/query.py", line 1881, in _fetch_all
    self._result_cache = list(self._iterable_class(self))
                         ^^^^^^^^^^^^^^^^^^^^^^^^^^^^^^^^
  File "/home/kayprogrammer/Documents/Projects/Django/bidout-auction-v5/env/lib/python3.11/site-packages/django/db/models/query.py", line 91, in __iter__
    results = compiler.execute_sql(
              ^^^^^^^^^^^^^^^^^^^^^
  File "/home/kayprogrammer/Documents/Projects/Django/bidout-auction-v5/env/lib/python3.11/site-packages/django/db/models/sql/compiler.py", line 1560, in execute_sql
    cursor = self.connection.cursor()
             ^^^^^^^^^^^^^^^^^^^^^^^^
  File "/home/kayprogrammer/Documents/Projects/Django/bidout-auction-v5/env/lib/python3.11/site-packages/django/utils/asyncio.py", line 24, in inner
    raise SynchronousOnlyOperation(message)
django.core.exceptions.SynchronousOnlyOperation: You cannot call this from an async context - use a thread or sync_to_async.
2023-07-04 11:04:52,388 django.request ERROR    Internal Server Error: /api/v5/auth/login/
2023-07-04 11:06:51,555 django.request WARNING  Not Found: /api/v5/auth/send-password-reset-otp/
2023-07-04 11:06:52,308 django.request ERROR    Internal Server Error: /api/v5/auth/login/
Traceback (most recent call last):
  File "/home/kayprogrammer/Documents/Projects/Django/bidout-auction-v5/env/lib/python3.11/site-packages/asgiref/sync.py", line 534, in thread_handler
    raise exc_info[1]
  File "/home/kayprogrammer/Documents/Projects/Django/bidout-auction-v5/env/lib/python3.11/site-packages/django/core/handlers/exception.py", line 42, in inner
    response = await get_response(request)
               ^^^^^^^^^^^^^^^^^^^^^^^^^^^
  File "/home/kayprogrammer/Documents/Projects/Django/bidout-auction-v5/env/lib/python3.11/site-packages/asgiref/sync.py", line 534, in thread_handler
    raise exc_info[1]
  File "/home/kayprogrammer/Documents/Projects/Django/bidout-auction-v5/env/lib/python3.11/site-packages/django/core/handlers/base.py", line 253, in _get_response_async
    response = await wrapped_callback(
               ^^^^^^^^^^^^^^^^^^^^^^^
  File "/home/kayprogrammer/Documents/Projects/Django/bidout-auction-v5/env/lib/python3.11/site-packages/ninja/operation.py", line 390, in _async_view
    return await cast(AsyncOperation, operation).run(request, *a, **kw)
           ^^^^^^^^^^^^^^^^^^^^^^^^^^^^^^^^^^^^^^^^^^^^^^^^^^^^^^^^^^^^
  File "/home/kayprogrammer/Documents/Projects/Django/bidout-auction-v5/env/lib/python3.11/site-packages/ninja/operation.py", line 259, in run
    error = await self._run_checks(request)
            ^^^^^^^^^^^^^^^^^^^^^^^^^^^^^^^
  File "/home/kayprogrammer/Documents/Projects/Django/bidout-auction-v5/env/lib/python3.11/site-packages/ninja/operation.py", line 274, in _run_checks
    error = await self._run_authentication(request)
            ^^^^^^^^^^^^^^^^^^^^^^^^^^^^^^^^^^^^^^^
  File "/home/kayprogrammer/Documents/Projects/Django/bidout-auction-v5/env/lib/python3.11/site-packages/ninja/operation.py", line 294, in _run_authentication
    return self.api.on_exception(request, exc)
           ^^^^^^^^^^^^^^^^^^^^^^^^^^^^^^^^^^^
  File "/home/kayprogrammer/Documents/Projects/Django/bidout-auction-v5/env/lib/python3.11/site-packages/ninja/main.py", line 471, in on_exception
    return handler(request, exc)
           ^^^^^^^^^^^^^^^^^^^^^
  File "/home/kayprogrammer/Documents/Projects/Django/bidout-auction-v5/env/lib/python3.11/site-packages/ninja/errors.py", line 104, in _default_exception
    raise exc  # let django deal with it
    ^^^^^^^^^
  File "/home/kayprogrammer/Documents/Projects/Django/bidout-auction-v5/env/lib/python3.11/site-packages/ninja/operation.py", line 292, in _run_authentication
    result = callback(request)
             ^^^^^^^^^^^^^^^^^
  File "/home/kayprogrammer/Documents/Projects/Django/bidout-auction-v5/env/lib/python3.11/site-packages/ninja/security/apikey.py", line 22, in __call__
    return self.authenticate(request, key)
           ^^^^^^^^^^^^^^^^^^^^^^^^^^^^^^^
  File "/home/kayprogrammer/Documents/Projects/Django/bidout-auction-v5/apps/common/utils.py", line 30, in authenticate
    guest = GuestUser.objects.filter(id=is_uuid(key)).first()
            ^^^^^^^^^^^^^^^^^^^^^^^^^^^^^^^^^^^^^^^^^^^^^^^^^
  File "/home/kayprogrammer/Documents/Projects/Django/bidout-auction-v5/env/lib/python3.11/site-packages/django/db/models/query.py", line 1057, in first
    for obj in queryset[:1]:
  File "/home/kayprogrammer/Documents/Projects/Django/bidout-auction-v5/env/lib/python3.11/site-packages/django/db/models/query.py", line 398, in __iter__
    self._fetch_all()
  File "/home/kayprogrammer/Documents/Projects/Django/bidout-auction-v5/env/lib/python3.11/site-packages/django/db/models/query.py", line 1881, in _fetch_all
    self._result_cache = list(self._iterable_class(self))
                         ^^^^^^^^^^^^^^^^^^^^^^^^^^^^^^^^
  File "/home/kayprogrammer/Documents/Projects/Django/bidout-auction-v5/env/lib/python3.11/site-packages/django/db/models/query.py", line 91, in __iter__
    results = compiler.execute_sql(
              ^^^^^^^^^^^^^^^^^^^^^
  File "/home/kayprogrammer/Documents/Projects/Django/bidout-auction-v5/env/lib/python3.11/site-packages/django/db/models/sql/compiler.py", line 1560, in execute_sql
    cursor = self.connection.cursor()
             ^^^^^^^^^^^^^^^^^^^^^^^^
  File "/home/kayprogrammer/Documents/Projects/Django/bidout-auction-v5/env/lib/python3.11/site-packages/django/utils/asyncio.py", line 24, in inner
    raise SynchronousOnlyOperation(message)
django.core.exceptions.SynchronousOnlyOperation: You cannot call this from an async context - use a thread or sync_to_async.
2023-07-04 11:07:47,043 django       ERROR    You cannot call this from an async context - use a thread or sync_to_async.
Traceback (most recent call last):
  File "/home/kayprogrammer/Documents/Projects/Django/bidout-auction-v5/env/lib/python3.11/site-packages/ninja/operation.py", line 292, in _run_authentication
    result = callback(request)
             ^^^^^^^^^^^^^^^^^
  File "/home/kayprogrammer/Documents/Projects/Django/bidout-auction-v5/env/lib/python3.11/site-packages/ninja/security/apikey.py", line 22, in __call__
    return self.authenticate(request, key)
           ^^^^^^^^^^^^^^^^^^^^^^^^^^^^^^^
  File "/home/kayprogrammer/Documents/Projects/Django/bidout-auction-v5/apps/common/utils.py", line 30, in authenticate
    guest = GuestUser.objects.get(id=is_uuid(key))
            ^^^^^^^^^^^^^^^^^^^^^^^^^^^^^^^^^^^^^^
  File "/home/kayprogrammer/Documents/Projects/Django/bidout-auction-v5/env/lib/python3.11/site-packages/django/db/models/manager.py", line 87, in manager_method
    return getattr(self.get_queryset(), name)(*args, **kwargs)
           ^^^^^^^^^^^^^^^^^^^^^^^^^^^^^^^^^^^^^^^^^^^^^^^^^^^
  File "/home/kayprogrammer/Documents/Projects/Django/bidout-auction-v5/env/lib/python3.11/site-packages/django/db/models/query.py", line 633, in get
    num = len(clone)
          ^^^^^^^^^^
  File "/home/kayprogrammer/Documents/Projects/Django/bidout-auction-v5/env/lib/python3.11/site-packages/django/db/models/query.py", line 380, in __len__
    self._fetch_all()
  File "/home/kayprogrammer/Documents/Projects/Django/bidout-auction-v5/env/lib/python3.11/site-packages/django/db/models/query.py", line 1881, in _fetch_all
    self._result_cache = list(self._iterable_class(self))
                         ^^^^^^^^^^^^^^^^^^^^^^^^^^^^^^^^
  File "/home/kayprogrammer/Documents/Projects/Django/bidout-auction-v5/env/lib/python3.11/site-packages/django/db/models/query.py", line 91, in __iter__
    results = compiler.execute_sql(
              ^^^^^^^^^^^^^^^^^^^^^
  File "/home/kayprogrammer/Documents/Projects/Django/bidout-auction-v5/env/lib/python3.11/site-packages/django/db/models/sql/compiler.py", line 1560, in execute_sql
    cursor = self.connection.cursor()
             ^^^^^^^^^^^^^^^^^^^^^^^^
  File "/home/kayprogrammer/Documents/Projects/Django/bidout-auction-v5/env/lib/python3.11/site-packages/django/utils/asyncio.py", line 24, in inner
    raise SynchronousOnlyOperation(message)
django.core.exceptions.SynchronousOnlyOperation: You cannot call this from an async context - use a thread or sync_to_async.
2023-07-04 11:07:47,074 django.request ERROR    Internal Server Error: /api/v5/auth/login/
2023-07-04 11:08:00,572 django       ERROR    You cannot call this from an async context - use a thread or sync_to_async.
Traceback (most recent call last):
  File "/home/kayprogrammer/Documents/Projects/Django/bidout-auction-v5/env/lib/python3.11/site-packages/ninja/operation.py", line 292, in _run_authentication
    result = callback(request)
             ^^^^^^^^^^^^^^^^^
  File "/home/kayprogrammer/Documents/Projects/Django/bidout-auction-v5/env/lib/python3.11/site-packages/ninja/security/apikey.py", line 22, in __call__
    return self.authenticate(request, key)
           ^^^^^^^^^^^^^^^^^^^^^^^^^^^^^^^
  File "/home/kayprogrammer/Documents/Projects/Django/bidout-auction-v5/apps/common/utils.py", line 30, in authenticate
    guest = GuestUser.objects.filter(id=is_uuid(key)).first()
            ^^^^^^^^^^^^^^^^^^^^^^^^^^^^^^^^^^^^^^^^^^^^^^^^^
  File "/home/kayprogrammer/Documents/Projects/Django/bidout-auction-v5/env/lib/python3.11/site-packages/django/db/models/query.py", line 1057, in first
    for obj in queryset[:1]:
  File "/home/kayprogrammer/Documents/Projects/Django/bidout-auction-v5/env/lib/python3.11/site-packages/django/db/models/query.py", line 398, in __iter__
    self._fetch_all()
  File "/home/kayprogrammer/Documents/Projects/Django/bidout-auction-v5/env/lib/python3.11/site-packages/django/db/models/query.py", line 1881, in _fetch_all
    self._result_cache = list(self._iterable_class(self))
                         ^^^^^^^^^^^^^^^^^^^^^^^^^^^^^^^^
  File "/home/kayprogrammer/Documents/Projects/Django/bidout-auction-v5/env/lib/python3.11/site-packages/django/db/models/query.py", line 91, in __iter__
    results = compiler.execute_sql(
              ^^^^^^^^^^^^^^^^^^^^^
  File "/home/kayprogrammer/Documents/Projects/Django/bidout-auction-v5/env/lib/python3.11/site-packages/django/db/models/sql/compiler.py", line 1560, in execute_sql
    cursor = self.connection.cursor()
             ^^^^^^^^^^^^^^^^^^^^^^^^
  File "/home/kayprogrammer/Documents/Projects/Django/bidout-auction-v5/env/lib/python3.11/site-packages/django/utils/asyncio.py", line 24, in inner
    raise SynchronousOnlyOperation(message)
django.core.exceptions.SynchronousOnlyOperation: You cannot call this from an async context - use a thread or sync_to_async.
2023-07-04 11:08:00,581 django.request ERROR    Internal Server Error: /api/v5/auth/login/
2023-07-04 11:08:26,109 django.request WARNING  Unauthorized: /api/v5/auth/login/
2023-07-04 11:11:20,836 django.request WARNING  Not Found: /api/v5/auth/send-password-reset-otp/
2023-07-04 11:11:21,598 django.request WARNING  Unauthorized: /api/v5/auth/login/
2023-07-04 11:11:21,955 django.request WARNING  Unauthorized: /api/v5/auth/login/
2023-07-04 11:11:57,392 django.request WARNING  Not Found: /api/v5/auth/send-password-reset-otp/
2023-07-04 11:12:42,147 django.request WARNING  Not Found: /api/v5/auth/send-password-reset-otp/
2023-07-04 11:13:42,541 django.request WARNING  Not Found: /api/v5/auth/send-password-reset-otp/
2023-07-04 11:13:43,768 django.request WARNING  Unprocessable Entity: /api/v5/auth/register/
2023-07-04 11:16:24,258 django.request WARNING  Not Found: /api/v5/auth/send-password-reset-otp/
2023-07-04 11:16:24,976 django.request WARNING  Unauthorized: /api/v5/auth/login/
2023-07-04 11:16:25,333 django.request WARNING  Unauthorized: /api/v5/auth/login/
2023-07-04 11:17:31,076 django.request WARNING  Unprocessable Entity: /api/v5/auth/register/
2023-07-04 11:18:00,296 django.request WARNING  Unprocessable Entity: /api/v5/auth/register/
2023-07-04 11:18:01,239 django.request WARNING  Not Found: /api/v5/auth/verify-email/
2023-07-04 11:18:19,181 django.request WARNING  Unprocessable Entity: /api/v5/auth/register/
2023-07-04 11:18:20,198 django.request WARNING  Not Found: /api/v5/auth/verify-email/
2023-07-04 11:18:47,414 django.request WARNING  Unprocessable Entity: /api/v5/auth/register/
2023-07-04 11:18:48,163 django.request WARNING  Not Found: /api/v5/auth/verify-email/
2023-07-04 11:19:22,571 django.request WARNING  Unprocessable Entity: /api/v5/auth/register/
2023-07-04 11:19:23,307 django.request WARNING  Not Found: /api/v5/auth/verify-email/
2023-07-04 11:19:46,688 django.request WARNING  Unprocessable Entity: /api/v5/auth/register/
2023-07-04 11:19:47,411 django.request WARNING  Not Found: /api/v5/auth/verify-email/
2023-07-04 11:20:24,462 django.request WARNING  Unprocessable Entity: /api/v5/auth/register/
2023-07-04 11:21:23,560 django.request WARNING  Unprocessable Entity: /api/v5/auth/register/
2023-07-04 11:21:24,555 django.request WARNING  Not Found: /api/v5/auth/resend-verification-email/
2023-07-04 11:21:25,731 django.request WARNING  Not Found: /api/v5/auth/verify-email/
2023-07-04 11:22:09,386 django.request WARNING  Unauthorized: /api/v5/auth/login/
2023-07-04 11:22:58,812 django.request WARNING  Unauthorized: /api/v5/auth/login/
2023-07-04 11:22:59,208 django.request WARNING  Unauthorized: /api/v5/auth/login/
2023-07-04 11:23:00,999 django.request WARNING  Unprocessable Entity: /api/v5/auth/register/
2023-07-04 11:23:01,763 django.request WARNING  Not Found: /api/v5/auth/resend-verification-email/
2023-07-04 11:23:02,488 django.request WARNING  Not Found: /api/v5/auth/verify-email/
2023-07-04 11:23:55,165 django.request WARNING  Unauthorized: /api/v5/auth/login/
2023-07-04 11:23:55,610 django.request WARNING  Unauthorized: /api/v5/auth/login/
2023-07-04 11:23:56,955 django.request ERROR    Internal Server Error: /api/v5/auth/refresh/
Traceback (most recent call last):
  File "/home/kayprogrammer/Documents/Projects/Django/bidout-auction-v5/env/lib/python3.11/site-packages/django/core/handlers/exception.py", line 55, in inner
    response = get_response(request)
               ^^^^^^^^^^^^^^^^^^^^^
  File "/home/kayprogrammer/Documents/Projects/Django/bidout-auction-v5/env/lib/python3.11/site-packages/django/core/handlers/base.py", line 197, in _get_response
    response = wrapped_callback(request, *callback_args, **callback_kwargs)
               ^^^^^^^^^^^^^^^^^^^^^^^^^^^^^^^^^^^^^^^^^^^^^^^^^^^^^^^^^^^^
  File "/home/kayprogrammer/Documents/Projects/Django/bidout-auction-v5/env/lib/python3.11/site-packages/asgiref/sync.py", line 209, in __call__
    raise RuntimeError(
RuntimeError: You cannot use AsyncToSync in the same thread as an async event loop - just await the async function directly.
2023-07-04 11:24:35,586 django.request WARNING  Unauthorized: /api/v5/auth/login/
2023-07-04 11:24:35,942 django.request WARNING  Unauthorized: /api/v5/auth/login/
2023-07-04 11:24:37,083 django.request WARNING  Not Found: /api/v5/auth/refresh/
2023-07-04 11:24:37,088 django.request WARNING  Unauthorized: /api/v5/auth/refresh/
2023-07-04 11:24:38,240 django.request WARNING  Unprocessable Entity: /api/v5/auth/register/
2023-07-04 11:24:39,256 django.request WARNING  Not Found: /api/v5/auth/resend-verification-email/
2023-07-04 11:24:40,046 django.request WARNING  Not Found: /api/v5/auth/verify-email/
2023-07-04 11:25:26,970 django.request WARNING  Not Found: /api/v5/auth/send-password-reset-otp/
2023-07-04 11:25:27,909 django.request WARNING  Unauthorized: /api/v5/auth/login/
2023-07-04 11:25:28,289 django.request WARNING  Unauthorized: /api/v5/auth/login/
2023-07-04 11:25:29,372 django.request WARNING  Not Found: /api/v5/auth/refresh/
2023-07-04 11:25:29,377 django.request WARNING  Unauthorized: /api/v5/auth/refresh/
2023-07-04 11:25:30,966 django.request WARNING  Unprocessable Entity: /api/v5/auth/register/
2023-07-04 11:25:31,834 django.request WARNING  Not Found: /api/v5/auth/resend-verification-email/
2023-07-04 11:25:32,738 django.request WARNING  Not Found: /api/v5/auth/verify-email/
2023-07-04 11:26:17,047 django.request WARNING  Not Found: /api/v5/auth/send-password-reset-otp/
2023-07-04 11:26:17,794 django.request WARNING  Unauthorized: /api/v5/auth/login/
2023-07-04 11:26:18,246 django.request WARNING  Unauthorized: /api/v5/auth/login/
2023-07-04 11:26:19,506 django.request WARNING  Not Found: /api/v5/auth/refresh/
2023-07-04 11:26:19,510 django.request WARNING  Unauthorized: /api/v5/auth/refresh/
2023-07-04 11:26:20,616 django.request WARNING  Unprocessable Entity: /api/v5/auth/register/
2023-07-04 11:26:21,349 django.request WARNING  Not Found: /api/v5/auth/resend-verification-email/
2023-07-04 11:26:22,072 django.request WARNING  Not Found: /api/v5/auth/set-new-password/
2023-07-04 11:26:22,079 django.request WARNING  Not Found: /api/v5/auth/set-new-password/
2023-07-04 11:26:23,386 django.request WARNING  Not Found: /api/v5/auth/verify-email/
2023-07-04 11:27:16,954 django.request WARNING  Not Found: /api/v5/auth/send-password-reset-otp/
2023-07-04 11:27:17,690 django.request WARNING  Unauthorized: /api/v5/auth/login/
2023-07-04 11:27:18,046 django.request WARNING  Unauthorized: /api/v5/auth/login/
2023-07-04 11:35:22,320 django.request WARNING  Unauthorized: /api/v5/auth/logout/
2023-07-04 11:38:17,893 django.request WARNING  Unauthorized: /api/v5/auth/logout/
2023-07-04 11:38:50,409 django.request WARNING  Unauthorized: /api/v5/auth/logout/
2023-07-04 11:39:41,795 django.request WARNING  Unauthorized: /api/v5/auth/logout/
2023-07-04 11:40:08,158 django.request WARNING  Unauthorized: /api/v5/auth/logout/
2023-07-04 11:43:32,884 django.request WARNING  Unauthorized: /api/v5/auth/logout/
2023-07-04 11:45:12,858 django.request WARNING  Unauthorized: /api/v5/auth/logout/
2023-07-04 11:46:18,714 django.request WARNING  Unauthorized: /api/v5/auth/logout/
2023-07-04 11:47:25,146 django.request WARNING  Not Found: /api/v5/auth/send-password-reset-otp/
2023-07-04 11:47:25,865 django.request WARNING  Unauthorized: /api/v5/auth/login/
2023-07-04 11:47:26,336 django.request WARNING  Unauthorized: /api/v5/auth/login/
2023-07-04 11:47:27,587 django.request WARNING  Unauthorized: /api/v5/auth/logout/
2023-07-04 11:53:15,102 django.request WARNING  Not Found: /api/v5/auth/send-password-reset-otp/
2023-07-04 11:53:15,947 django.request WARNING  Unauthorized: /api/v5/auth/login/
2023-07-04 11:53:16,381 django.request WARNING  Unauthorized: /api/v5/auth/login/
2023-07-04 11:53:17,492 django.request WARNING  Unauthorized: /api/v5/auth/logout/
2023-07-04 11:53:18,218 django.request WARNING  Not Found: /api/v5/auth/refresh/
2023-07-04 11:55:39,276 django.request WARNING  Not Found: /api/v5/auth/send-password-reset-otp/
2023-07-04 11:55:40,170 django.request WARNING  Unauthorized: /api/v5/auth/login/
2023-07-04 11:55:40,727 django.request WARNING  Unauthorized: /api/v5/auth/login/
2023-07-04 11:55:41,900 django.request WARNING  Unauthorized: /api/v5/auth/logout/
2023-07-04 11:55:43,027 django.request WARNING  Not Found: /api/v5/auth/refresh/
2023-07-04 11:55:43,034 django.request WARNING  Unauthorized: /api/v5/auth/refresh/
2023-07-04 11:55:44,213 django.request WARNING  Unprocessable Entity: /api/v5/auth/register/
2023-07-04 11:55:45,012 django.request WARNING  Not Found: /api/v5/auth/resend-verification-email/
2023-07-04 11:55:45,729 django.request WARNING  Not Found: /api/v5/auth/set-new-password/
2023-07-04 11:55:45,736 django.request WARNING  Not Found: /api/v5/auth/set-new-password/
2023-07-04 11:55:46,926 django.request WARNING  Not Found: /api/v5/auth/verify-email/
2023-07-04 12:34:27,956 django.request WARNING  Not Found: //api/v5/listings/
2023-07-04 12:34:36,475 django       ERROR    'ASGIRequest' object has no attribute 'auth'
Traceback (most recent call last):
  File "/home/kayprogrammer/Documents/Projects/Django/bidout-auction-v5/env/lib/python3.11/site-packages/ninja/operation.py", line 265, in run
    result = await self.view_func(request, **values)
             ^^^^^^^^^^^^^^^^^^^^^^^^^^^^^^^^^^^^^^^
  File "/home/kayprogrammer/Documents/Projects/Django/bidout-auction-v5/apps/listings/views.py", line 24, in retrieve_listings
    client = await request.auth
                   ^^^^^^^^^^^^
AttributeError: 'ASGIRequest' object has no attribute 'auth'
2023-07-04 12:34:36,479 django.request ERROR    Internal Server Error: /api/v5/listings/
2023-07-04 12:35:00,982 django       ERROR    name 'client' is not defined
Traceback (most recent call last):
  File "/home/kayprogrammer/Documents/Projects/Django/bidout-auction-v5/env/lib/python3.11/site-packages/ninja/operation.py", line 265, in run
    result = await self.view_func(request, **values)
             ^^^^^^^^^^^^^^^^^^^^^^^^^^^^^^^^^^^^^^^
  File "/home/kayprogrammer/Documents/Projects/Django/bidout-auction-v5/apps/listings/views.py", line 32, in retrieve_listings
    Q(user_id=client.id if client else None)
                           ^^^^^^
NameError: name 'client' is not defined
2023-07-04 12:35:00,985 django.request ERROR    Internal Server Error: /api/v5/listings/
2023-07-04 12:35:10,012 django       ERROR    'ASGIRequest' object has no attribute 'auth'
Traceback (most recent call last):
  File "/home/kayprogrammer/Documents/Projects/Django/bidout-auction-v5/env/lib/python3.11/site-packages/ninja/operation.py", line 265, in run
    result = await self.view_func(request, **values)
             ^^^^^^^^^^^^^^^^^^^^^^^^^^^^^^^^^^^^^^^
  File "/home/kayprogrammer/Documents/Projects/Django/bidout-auction-v5/apps/listings/views.py", line 24, in retrieve_listings
    client = await request.auth
                   ^^^^^^^^^^^^
AttributeError: 'ASGIRequest' object has no attribute 'auth'
2023-07-04 12:35:10,022 django.request ERROR    Internal Server Error: /api/v5/listings/
2023-07-04 12:35:39,365 django       ERROR    6 validation errors for NinjaResponseSchema
response -> data -> 0 -> watchlist
  value could not be parsed to a boolean (type=type_error.bool)
response -> data -> 1 -> watchlist
  value could not be parsed to a boolean (type=type_error.bool)
response -> data -> 2 -> watchlist
  value could not be parsed to a boolean (type=type_error.bool)
response -> data -> 3 -> watchlist
  value could not be parsed to a boolean (type=type_error.bool)
response -> data -> 4 -> watchlist
  value could not be parsed to a boolean (type=type_error.bool)
response -> data -> 5 -> watchlist
  value could not be parsed to a boolean (type=type_error.bool)
Traceback (most recent call last):
  File "/home/kayprogrammer/Documents/Projects/Django/bidout-auction-v5/env/lib/python3.11/site-packages/ninja/operation.py", line 266, in run
    return self._result_to_response(request, result, temporal_response)
           ^^^^^^^^^^^^^^^^^^^^^^^^^^^^^^^^^^^^^^^^^^^^^^^^^^^^^^^^^^^^
  File "/home/kayprogrammer/Documents/Projects/Django/bidout-auction-v5/env/lib/python3.11/site-packages/ninja/operation.py", line 202, in _result_to_response
    result = response_model.from_orm(resp_object).dict(
             ^^^^^^^^^^^^^^^^^^^^^^^^^^^^^^^^^^^^
  File "/home/kayprogrammer/Documents/Projects/Django/bidout-auction-v5/env/lib/python3.11/site-packages/ninja/schema.py", line 164, in from_orm
    return super().from_orm(obj)
           ^^^^^^^^^^^^^^^^^^^^^
  File "pydantic/main.py", line 579, in pydantic.main.BaseModel.from_orm
pydantic.error_wrappers.ValidationError: 6 validation errors for NinjaResponseSchema
response -> data -> 0 -> watchlist
  value could not be parsed to a boolean (type=type_error.bool)
response -> data -> 1 -> watchlist
  value could not be parsed to a boolean (type=type_error.bool)
response -> data -> 2 -> watchlist
  value could not be parsed to a boolean (type=type_error.bool)
response -> data -> 3 -> watchlist
  value could not be parsed to a boolean (type=type_error.bool)
response -> data -> 4 -> watchlist
  value could not be parsed to a boolean (type=type_error.bool)
response -> data -> 5 -> watchlist
  value could not be parsed to a boolean (type=type_error.bool)
2023-07-04 12:35:39,390 django.request ERROR    Internal Server Error: /api/v5/listings/
2023-07-04 12:36:04,655 django.request WARNING  Unprocessable Entity: /api/v5/listings/
2023-07-04 12:37:55,778 django       ERROR    6 validation errors for NinjaResponseSchema
response -> data -> 0 -> watchlist
  value could not be parsed to a boolean (type=type_error.bool)
response -> data -> 1 -> watchlist
  value could not be parsed to a boolean (type=type_error.bool)
response -> data -> 2 -> watchlist
  value could not be parsed to a boolean (type=type_error.bool)
response -> data -> 3 -> watchlist
  value could not be parsed to a boolean (type=type_error.bool)
response -> data -> 4 -> watchlist
  value could not be parsed to a boolean (type=type_error.bool)
response -> data -> 5 -> watchlist
  value could not be parsed to a boolean (type=type_error.bool)
Traceback (most recent call last):
  File "/home/kayprogrammer/Documents/Projects/Django/bidout-auction-v5/env/lib/python3.11/site-packages/ninja/operation.py", line 266, in run
    return self._result_to_response(request, result, temporal_response)
           ^^^^^^^^^^^^^^^^^^^^^^^^^^^^^^^^^^^^^^^^^^^^^^^^^^^^^^^^^^^^
  File "/home/kayprogrammer/Documents/Projects/Django/bidout-auction-v5/env/lib/python3.11/site-packages/ninja/operation.py", line 202, in _result_to_response
    result = response_model.from_orm(resp_object).dict(
             ^^^^^^^^^^^^^^^^^^^^^^^^^^^^^^^^^^^^
  File "/home/kayprogrammer/Documents/Projects/Django/bidout-auction-v5/env/lib/python3.11/site-packages/ninja/schema.py", line 164, in from_orm
    return super().from_orm(obj)
           ^^^^^^^^^^^^^^^^^^^^^
  File "pydantic/main.py", line 579, in pydantic.main.BaseModel.from_orm
pydantic.error_wrappers.ValidationError: 6 validation errors for NinjaResponseSchema
response -> data -> 0 -> watchlist
  value could not be parsed to a boolean (type=type_error.bool)
response -> data -> 1 -> watchlist
  value could not be parsed to a boolean (type=type_error.bool)
response -> data -> 2 -> watchlist
  value could not be parsed to a boolean (type=type_error.bool)
response -> data -> 3 -> watchlist
  value could not be parsed to a boolean (type=type_error.bool)
response -> data -> 4 -> watchlist
  value could not be parsed to a boolean (type=type_error.bool)
response -> data -> 5 -> watchlist
  value could not be parsed to a boolean (type=type_error.bool)
2023-07-04 12:37:55,785 django.request ERROR    Internal Server Error: /api/v5/listings/
2023-07-04 12:47:16,826 django       ERROR    'File' object has no attribute 'get_image'
Traceback (most recent call last):
  File "/home/kayprogrammer/Documents/Projects/Django/bidout-auction-v5/env/lib/python3.11/site-packages/ninja/operation.py", line 266, in run
    return self._result_to_response(request, result, temporal_response)
           ^^^^^^^^^^^^^^^^^^^^^^^^^^^^^^^^^^^^^^^^^^^^^^^^^^^^^^^^^^^^
  File "/home/kayprogrammer/Documents/Projects/Django/bidout-auction-v5/env/lib/python3.11/site-packages/ninja/operation.py", line 202, in _result_to_response
    result = response_model.from_orm(resp_object).dict(
             ^^^^^^^^^^^^^^^^^^^^^^^^^^^^^^^^^^^^
  File "/home/kayprogrammer/Documents/Projects/Django/bidout-auction-v5/env/lib/python3.11/site-packages/ninja/schema.py", line 164, in from_orm
    return super().from_orm(obj)
           ^^^^^^^^^^^^^^^^^^^^^
  File "pydantic/main.py", line 577, in pydantic.main.BaseModel.from_orm
  File "pydantic/main.py", line 1076, in pydantic.main.validate_model
  File "pydantic/fields.py", line 884, in pydantic.fields.ModelField.validate
  File "pydantic/fields.py", line 1101, in pydantic.fields.ModelField._validate_singleton
  File "pydantic/fields.py", line 1157, in pydantic.fields.ModelField._apply_validators
  File "pydantic/class_validators.py", line 337, in pydantic.class_validators._generic_validator_basic.lambda13
  File "pydantic/main.py", line 711, in pydantic.main.BaseModel.validate
  File "pydantic/main.py", line 339, in pydantic.main.BaseModel.__init__
  File "pydantic/main.py", line 1076, in pydantic.main.validate_model
  File "pydantic/fields.py", line 895, in pydantic.fields.ModelField.validate
  File "pydantic/fields.py", line 928, in pydantic.fields.ModelField._validate_sequence_like
  File "pydantic/fields.py", line 1094, in pydantic.fields.ModelField._validate_singleton
  File "pydantic/fields.py", line 884, in pydantic.fields.ModelField.validate
  File "pydantic/fields.py", line 1101, in pydantic.fields.ModelField._validate_singleton
  File "pydantic/fields.py", line 1157, in pydantic.fields.ModelField._apply_validators
  File "pydantic/class_validators.py", line 337, in pydantic.class_validators._generic_validator_basic.lambda13
  File "pydantic/main.py", line 713, in pydantic.main.BaseModel.validate
  File "pydantic/main.py", line 577, in pydantic.main.BaseModel.from_orm
  File "pydantic/main.py", line 1076, in pydantic.main.validate_model
  File "pydantic/fields.py", line 867, in pydantic.fields.ModelField.validate
  File "pydantic/fields.py", line 1157, in pydantic.fields.ModelField._apply_validators
  File "pydantic/class_validators.py", line 304, in pydantic.class_validators._generic_validator_cls.lambda4
  File "/home/kayprogrammer/Documents/Projects/Django/bidout-auction-v5/apps/listings/schemas.py", line 76, in assemble_image_url
    return v.get_image
           ^^^^^^^^^^^
AttributeError: 'File' object has no attribute 'get_image'
2023-07-04 12:47:16,831 django.request ERROR    Internal Server Error: /api/v5/listings/
2023-07-04 14:51:37,277 jazzmin.templatetags.jazzmin WARNING  avatar field must be an ImageField/URLField on the user model, or a callable
2023-07-04 15:03:09,766 django       ERROR    6 validation errors for NinjaResponseSchema
response -> data -> 0 -> category
  str type expected (type=type_error.str)
response -> data -> 1 -> category
  str type expected (type=type_error.str)
response -> data -> 2 -> category
  str type expected (type=type_error.str)
response -> data -> 3 -> category
  str type expected (type=type_error.str)
response -> data -> 4 -> category
  str type expected (type=type_error.str)
response -> data -> 5 -> category
  str type expected (type=type_error.str)
Traceback (most recent call last):
  File "/home/kayprogrammer/Documents/Projects/Django/bidout-auction-v5/env/lib/python3.11/site-packages/ninja/operation.py", line 266, in run
    return self._result_to_response(request, result, temporal_response)
           ^^^^^^^^^^^^^^^^^^^^^^^^^^^^^^^^^^^^^^^^^^^^^^^^^^^^^^^^^^^^
  File "/home/kayprogrammer/Documents/Projects/Django/bidout-auction-v5/env/lib/python3.11/site-packages/ninja/operation.py", line 202, in _result_to_response
    result = response_model.from_orm(resp_object).dict(
             ^^^^^^^^^^^^^^^^^^^^^^^^^^^^^^^^^^^^
  File "/home/kayprogrammer/Documents/Projects/Django/bidout-auction-v5/env/lib/python3.11/site-packages/ninja/schema.py", line 164, in from_orm
    return super().from_orm(obj)
           ^^^^^^^^^^^^^^^^^^^^^
  File "pydantic/main.py", line 579, in pydantic.main.BaseModel.from_orm
pydantic.error_wrappers.ValidationError: 6 validation errors for NinjaResponseSchema
response -> data -> 0 -> category
  str type expected (type=type_error.str)
response -> data -> 1 -> category
  str type expected (type=type_error.str)
response -> data -> 2 -> category
  str type expected (type=type_error.str)
response -> data -> 3 -> category
  str type expected (type=type_error.str)
response -> data -> 4 -> category
  str type expected (type=type_error.str)
response -> data -> 5 -> category
  str type expected (type=type_error.str)
2023-07-04 15:03:09,847 django.request ERROR    Internal Server Error: /api/v5/listings/
2023-07-04 15:03:45,222 django       ERROR    name 'CustomResponse' is not defined
Traceback (most recent call last):
  File "/home/kayprogrammer/Documents/Projects/Django/bidout-auction-v5/env/lib/python3.11/site-packages/ninja/operation.py", line 265, in run
    result = await self.view_func(request, **values)
             ^^^^^^^^^^^^^^^^^^^^^^^^^^^^^^^^^^^^^^^
  File "/home/kayprogrammer/Documents/Projects/Django/bidout-auction-v5/apps/listings/views.py", line 71, in retrieve_listing_detail
    return CustomResponse.success(
           ^^^^^^^^^^^^^^
NameError: name 'CustomResponse' is not defined
2023-07-04 15:03:45,231 django.request ERROR    Internal Server Error: /api/v5/listings/detail/iphone-11-pro-max-all-variants-available-for-sale/
2023-07-04 15:27:19,589 django       ERROR    'ASGIRequest' object has no attribute 'auth'
Traceback (most recent call last):
  File "/home/kayprogrammer/Documents/Projects/Django/bidout-auction-v5/env/lib/python3.11/site-packages/ninja/operation.py", line 265, in run
    result = await self.view_func(request, **values)
             ^^^^^^^^^^^^^^^^^^^^^^^^^^^^^^^^^^^^^^^
  File "/home/kayprogrammer/Documents/Projects/Django/bidout-auction-v5/apps/listings/views.py", line 83, in retrieve_watchlist
    client = await request.auth
                   ^^^^^^^^^^^^
AttributeError: 'ASGIRequest' object has no attribute 'auth'
2023-07-04 15:27:19,672 django.request ERROR    Internal Server Error: /api/v5/listings/watchlist/
2023-07-04 15:28:44,597 django.request WARNING  Not Found: /api/v5/listings/watchlist/
2023-07-04 15:29:27,071 django       ERROR    unhashable type: 'dict'
Traceback (most recent call last):
  File "/home/kayprogrammer/Documents/Projects/Django/bidout-auction-v5/env/lib/python3.11/site-packages/ninja/operation.py", line 266, in run
    return self._result_to_response(request, result, temporal_response)
           ^^^^^^^^^^^^^^^^^^^^^^^^^^^^^^^^^^^^^^^^^^^^^^^^^^^^^^^^^^^^
  File "/home/kayprogrammer/Documents/Projects/Django/bidout-auction-v5/env/lib/python3.11/site-packages/ninja/operation.py", line 179, in _result_to_response
    if status in self.response_models:
       ^^^^^^^^^^^^^^^^^^^^^^^^^^^^^^
TypeError: unhashable type: 'dict'
2023-07-04 15:29:27,074 django.request ERROR    Internal Server Error: /api/v5/listings/watchlist/
2023-07-04 15:31:19,229 django       ERROR    Response.__init__() takes 2 positional arguments but 3 were given
Traceback (most recent call last):
  File "/home/kayprogrammer/Documents/Projects/Django/bidout-auction-v5/env/lib/python3.11/site-packages/ninja/operation.py", line 265, in run
    result = await self.view_func(request, **values)
             ^^^^^^^^^^^^^^^^^^^^^^^^^^^^^^^^^^^^^^^
  File "/home/kayprogrammer/Documents/Projects/Django/bidout-auction-v5/apps/listings/views.py", line 146, in post
    return Response({
           ^^^^^^^^^^
TypeError: Response.__init__() takes 2 positional arguments but 3 were given
2023-07-04 15:31:19,234 django.request ERROR    Internal Server Error: /api/v5/listings/watchlist/
2023-07-04 15:36:59,244 django.request WARNING  Not Found: /api/v5/listings/watchlist/
2023-07-04 15:37:24,386 django       ERROR    'Listing' object is not a mapping
Traceback (most recent call last):
  File "/home/kayprogrammer/Documents/Projects/Django/bidout-auction-v5/env/lib/python3.11/site-packages/ninja/operation.py", line 265, in run
    result = await self.view_func(request, **values)
             ^^^^^^^^^^^^^^^^^^^^^^^^^^^^^^^^^^^^^^^
  File "/home/kayprogrammer/Documents/Projects/Django/bidout-auction-v5/apps/listings/views.py", line 102, in retrieve_watchlist
    data = [{"watchlist": True, **watchlist.listing} for watchlist in watchlists]
           ^^^^^^^^^^^^^^^^^^^^^^^^^^^^^^^^^^^^^^^^^^^^^^^^^^^^^^^^^^^^^^^^^^^^^^
  File "/home/kayprogrammer/Documents/Projects/Django/bidout-auction-v5/apps/listings/views.py", line 102, in <listcomp>
    data = [{"watchlist": True, **watchlist.listing} for watchlist in watchlists]
            ^^^^^^^^^^^^^^^^^^^^^^^^^^^^^^^^^^^^^^^^
TypeError: 'Listing' object is not a mapping
2023-07-04 15:37:24,390 django.request ERROR    Internal Server Error: /api/v5/listings/watchlist/
2023-07-04 15:37:49,791 django       ERROR    'Listing' object is not a mapping
Traceback (most recent call last):
  File "/home/kayprogrammer/Documents/Projects/Django/bidout-auction-v5/env/lib/python3.11/site-packages/ninja/operation.py", line 265, in run
    result = await self.view_func(request, **values)
             ^^^^^^^^^^^^^^^^^^^^^^^^^^^^^^^^^^^^^^^
  File "/home/kayprogrammer/Documents/Projects/Django/bidout-auction-v5/apps/listings/views.py", line 102, in retrieve_watchlist
    data = [{"watchlist": True, **watchlist.listing} for watchlist in watchlists]
           ^^^^^^^^^^^^^^^^^^^^^^^^^^^^^^^^^^^^^^^^^^^^^^^^^^^^^^^^^^^^^^^^^^^^^^
  File "/home/kayprogrammer/Documents/Projects/Django/bidout-auction-v5/apps/listings/views.py", line 102, in <listcomp>
    data = [{"watchlist": True, **watchlist.listing} for watchlist in watchlists]
            ^^^^^^^^^^^^^^^^^^^^^^^^^^^^^^^^^^^^^^^^
TypeError: 'Listing' object is not a mapping
2023-07-04 15:37:49,797 django.request ERROR    Internal Server Error: /api/v5/listings/watchlist/
2023-07-04 15:38:11,235 django       ERROR    'Listing' object has no attribute 'dict'
Traceback (most recent call last):
  File "/home/kayprogrammer/Documents/Projects/Django/bidout-auction-v5/env/lib/python3.11/site-packages/ninja/operation.py", line 265, in run
    result = await self.view_func(request, **values)
             ^^^^^^^^^^^^^^^^^^^^^^^^^^^^^^^^^^^^^^^
  File "/home/kayprogrammer/Documents/Projects/Django/bidout-auction-v5/apps/listings/views.py", line 102, in retrieve_watchlist
    data = [{"watchlist": True, **watchlist.listing.dict()} for watchlist in watchlists]
           ^^^^^^^^^^^^^^^^^^^^^^^^^^^^^^^^^^^^^^^^^^^^^^^^^^^^^^^^^^^^^^^^^^^^^^^^^^^^^
  File "/home/kayprogrammer/Documents/Projects/Django/bidout-auction-v5/apps/listings/views.py", line 102, in <listcomp>
    data = [{"watchlist": True, **watchlist.listing.dict()} for watchlist in watchlists]
                                  ^^^^^^^^^^^^^^^^^^^^^^
AttributeError: 'Listing' object has no attribute 'dict'
2023-07-04 15:38:11,238 django.request ERROR    Internal Server Error: /api/v5/listings/watchlist/
2023-07-04 15:39:23,323 django       ERROR    Object of type ModelState is not JSON serializable
Traceback (most recent call last):
  File "/home/kayprogrammer/Documents/Projects/Django/bidout-auction-v5/env/lib/python3.11/site-packages/ninja/operation.py", line 266, in run
    return self._result_to_response(request, result, temporal_response)
           ^^^^^^^^^^^^^^^^^^^^^^^^^^^^^^^^^^^^^^^^^^^^^^^^^^^^^^^^^^^^
  File "/home/kayprogrammer/Documents/Projects/Django/bidout-auction-v5/env/lib/python3.11/site-packages/ninja/operation.py", line 192, in _result_to_response
    return self.api.create_response(
           ^^^^^^^^^^^^^^^^^^^^^^^^^
  File "/home/kayprogrammer/Documents/Projects/Django/bidout-auction-v5/env/lib/python3.11/site-packages/ninja/main.py", line 416, in create_response
    content = self.renderer.render(request, data, response_status=status)
              ^^^^^^^^^^^^^^^^^^^^^^^^^^^^^^^^^^^^^^^^^^^^^^^^^^^^^^^^^^^
  File "/home/kayprogrammer/Documents/Projects/Django/bidout-auction-v5/env/lib/python3.11/site-packages/ninja/renderers.py", line 25, in render
    return json.dumps(data, cls=self.encoder_class, **self.json_dumps_params)
           ^^^^^^^^^^^^^^^^^^^^^^^^^^^^^^^^^^^^^^^^^^^^^^^^^^^^^^^^^^^^^^^^^^
  File "/usr/lib/python3.11/json/__init__.py", line 238, in dumps
    **kw).encode(obj)
          ^^^^^^^^^^^
  File "/usr/lib/python3.11/json/encoder.py", line 200, in encode
    chunks = self.iterencode(o, _one_shot=True)
             ^^^^^^^^^^^^^^^^^^^^^^^^^^^^^^^^^^
  File "/usr/lib/python3.11/json/encoder.py", line 258, in iterencode
    return _iterencode(o, 0)
           ^^^^^^^^^^^^^^^^^
  File "/home/kayprogrammer/Documents/Projects/Django/bidout-auction-v5/env/lib/python3.11/site-packages/ninja/responses.py", line 25, in default
    return super().default(o)
           ^^^^^^^^^^^^^^^^^^
  File "/home/kayprogrammer/Documents/Projects/Django/bidout-auction-v5/env/lib/python3.11/site-packages/django/core/serializers/json.py", line 106, in default
    return super().default(o)
           ^^^^^^^^^^^^^^^^^^
  File "/usr/lib/python3.11/json/encoder.py", line 180, in default
    raise TypeError(f'Object of type {o.__class__.__name__} '
TypeError: Object of type ModelState is not JSON serializable
2023-07-04 15:39:23,414 django.request ERROR    Internal Server Error: /api/v5/listings/watchlist/
2023-07-04 15:39:51,008 django       ERROR    Object of type ModelState is not JSON serializable
Traceback (most recent call last):
  File "/home/kayprogrammer/Documents/Projects/Django/bidout-auction-v5/env/lib/python3.11/site-packages/ninja/operation.py", line 266, in run
    return self._result_to_response(request, result, temporal_response)
           ^^^^^^^^^^^^^^^^^^^^^^^^^^^^^^^^^^^^^^^^^^^^^^^^^^^^^^^^^^^^
  File "/home/kayprogrammer/Documents/Projects/Django/bidout-auction-v5/env/lib/python3.11/site-packages/ninja/operation.py", line 192, in _result_to_response
    return self.api.create_response(
           ^^^^^^^^^^^^^^^^^^^^^^^^^
  File "/home/kayprogrammer/Documents/Projects/Django/bidout-auction-v5/env/lib/python3.11/site-packages/ninja/main.py", line 416, in create_response
    content = self.renderer.render(request, data, response_status=status)
              ^^^^^^^^^^^^^^^^^^^^^^^^^^^^^^^^^^^^^^^^^^^^^^^^^^^^^^^^^^^
  File "/home/kayprogrammer/Documents/Projects/Django/bidout-auction-v5/env/lib/python3.11/site-packages/ninja/renderers.py", line 25, in render
    return json.dumps(data, cls=self.encoder_class, **self.json_dumps_params)
           ^^^^^^^^^^^^^^^^^^^^^^^^^^^^^^^^^^^^^^^^^^^^^^^^^^^^^^^^^^^^^^^^^^
  File "/usr/lib/python3.11/json/__init__.py", line 238, in dumps
    **kw).encode(obj)
          ^^^^^^^^^^^
  File "/usr/lib/python3.11/json/encoder.py", line 200, in encode
    chunks = self.iterencode(o, _one_shot=True)
             ^^^^^^^^^^^^^^^^^^^^^^^^^^^^^^^^^^
  File "/usr/lib/python3.11/json/encoder.py", line 258, in iterencode
    return _iterencode(o, 0)
           ^^^^^^^^^^^^^^^^^
  File "/home/kayprogrammer/Documents/Projects/Django/bidout-auction-v5/env/lib/python3.11/site-packages/ninja/responses.py", line 25, in default
    return super().default(o)
           ^^^^^^^^^^^^^^^^^^
  File "/home/kayprogrammer/Documents/Projects/Django/bidout-auction-v5/env/lib/python3.11/site-packages/django/core/serializers/json.py", line 106, in default
    return super().default(o)
           ^^^^^^^^^^^^^^^^^^
  File "/usr/lib/python3.11/json/encoder.py", line 180, in default
    raise TypeError(f'Object of type {o.__class__.__name__} '
TypeError: Object of type ModelState is not JSON serializable
2023-07-04 15:39:51,019 django.request ERROR    Internal Server Error: /api/v5/listings/watchlist/
2023-07-04 15:40:19,937 django       ERROR    Object of type ModelState is not JSON serializable
Traceback (most recent call last):
  File "/home/kayprogrammer/Documents/Projects/Django/bidout-auction-v5/env/lib/python3.11/site-packages/ninja/operation.py", line 266, in run
    return self._result_to_response(request, result, temporal_response)
           ^^^^^^^^^^^^^^^^^^^^^^^^^^^^^^^^^^^^^^^^^^^^^^^^^^^^^^^^^^^^
  File "/home/kayprogrammer/Documents/Projects/Django/bidout-auction-v5/env/lib/python3.11/site-packages/ninja/operation.py", line 192, in _result_to_response
    return self.api.create_response(
           ^^^^^^^^^^^^^^^^^^^^^^^^^
  File "/home/kayprogrammer/Documents/Projects/Django/bidout-auction-v5/env/lib/python3.11/site-packages/ninja/main.py", line 416, in create_response
    content = self.renderer.render(request, data, response_status=status)
              ^^^^^^^^^^^^^^^^^^^^^^^^^^^^^^^^^^^^^^^^^^^^^^^^^^^^^^^^^^^
  File "/home/kayprogrammer/Documents/Projects/Django/bidout-auction-v5/env/lib/python3.11/site-packages/ninja/renderers.py", line 25, in render
    return json.dumps(data, cls=self.encoder_class, **self.json_dumps_params)
           ^^^^^^^^^^^^^^^^^^^^^^^^^^^^^^^^^^^^^^^^^^^^^^^^^^^^^^^^^^^^^^^^^^
  File "/usr/lib/python3.11/json/__init__.py", line 238, in dumps
    **kw).encode(obj)
          ^^^^^^^^^^^
  File "/usr/lib/python3.11/json/encoder.py", line 200, in encode
    chunks = self.iterencode(o, _one_shot=True)
             ^^^^^^^^^^^^^^^^^^^^^^^^^^^^^^^^^^
  File "/usr/lib/python3.11/json/encoder.py", line 258, in iterencode
    return _iterencode(o, 0)
           ^^^^^^^^^^^^^^^^^
  File "/home/kayprogrammer/Documents/Projects/Django/bidout-auction-v5/env/lib/python3.11/site-packages/ninja/responses.py", line 25, in default
    return super().default(o)
           ^^^^^^^^^^^^^^^^^^
  File "/home/kayprogrammer/Documents/Projects/Django/bidout-auction-v5/env/lib/python3.11/site-packages/django/core/serializers/json.py", line 106, in default
    return super().default(o)
           ^^^^^^^^^^^^^^^^^^
  File "/usr/lib/python3.11/json/encoder.py", line 180, in default
    raise TypeError(f'Object of type {o.__class__.__name__} '
TypeError: Object of type ModelState is not JSON serializable
2023-07-04 15:40:19,946 django.request ERROR    Internal Server Error: /api/v5/listings/watchlist/
2023-07-04 15:40:47,638 django       ERROR    Object of type ModelState is not JSON serializable
Traceback (most recent call last):
  File "/home/kayprogrammer/Documents/Projects/Django/bidout-auction-v5/env/lib/python3.11/site-packages/ninja/operation.py", line 266, in run
    return self._result_to_response(request, result, temporal_response)
           ^^^^^^^^^^^^^^^^^^^^^^^^^^^^^^^^^^^^^^^^^^^^^^^^^^^^^^^^^^^^
  File "/home/kayprogrammer/Documents/Projects/Django/bidout-auction-v5/env/lib/python3.11/site-packages/ninja/operation.py", line 192, in _result_to_response
    return self.api.create_response(
           ^^^^^^^^^^^^^^^^^^^^^^^^^
  File "/home/kayprogrammer/Documents/Projects/Django/bidout-auction-v5/env/lib/python3.11/site-packages/ninja/main.py", line 416, in create_response
    content = self.renderer.render(request, data, response_status=status)
              ^^^^^^^^^^^^^^^^^^^^^^^^^^^^^^^^^^^^^^^^^^^^^^^^^^^^^^^^^^^
  File "/home/kayprogrammer/Documents/Projects/Django/bidout-auction-v5/env/lib/python3.11/site-packages/ninja/renderers.py", line 25, in render
    return json.dumps(data, cls=self.encoder_class, **self.json_dumps_params)
           ^^^^^^^^^^^^^^^^^^^^^^^^^^^^^^^^^^^^^^^^^^^^^^^^^^^^^^^^^^^^^^^^^^
  File "/usr/lib/python3.11/json/__init__.py", line 238, in dumps
    **kw).encode(obj)
          ^^^^^^^^^^^
  File "/usr/lib/python3.11/json/encoder.py", line 200, in encode
    chunks = self.iterencode(o, _one_shot=True)
             ^^^^^^^^^^^^^^^^^^^^^^^^^^^^^^^^^^
  File "/usr/lib/python3.11/json/encoder.py", line 258, in iterencode
    return _iterencode(o, 0)
           ^^^^^^^^^^^^^^^^^
  File "/home/kayprogrammer/Documents/Projects/Django/bidout-auction-v5/env/lib/python3.11/site-packages/ninja/responses.py", line 25, in default
    return super().default(o)
           ^^^^^^^^^^^^^^^^^^
  File "/home/kayprogrammer/Documents/Projects/Django/bidout-auction-v5/env/lib/python3.11/site-packages/django/core/serializers/json.py", line 106, in default
    return super().default(o)
           ^^^^^^^^^^^^^^^^^^
  File "/usr/lib/python3.11/json/encoder.py", line 180, in default
    raise TypeError(f'Object of type {o.__class__.__name__} '
TypeError: Object of type ModelState is not JSON serializable
2023-07-04 15:40:47,647 django.request ERROR    Internal Server Error: /api/v5/listings/watchlist/
2023-07-04 15:44:06,451 django       ERROR    4 validation errors for NinjaResponseSchema
response -> data -> 0 -> auctioneer
  field required (type=value_error.missing)
response -> data -> 0 -> time_left_seconds
  field required (type=value_error.missing)
response -> data -> 0 -> active
  '>' not supported between instances of 'NoneType' and 'int' (type=type_error)
response -> data -> 0 -> watchlist
  object of type 'bool' has no len() (type=type_error)
Traceback (most recent call last):
  File "/home/kayprogrammer/Documents/Projects/Django/bidout-auction-v5/env/lib/python3.11/site-packages/ninja/operation.py", line 266, in run
    return self._result_to_response(request, result, temporal_response)
           ^^^^^^^^^^^^^^^^^^^^^^^^^^^^^^^^^^^^^^^^^^^^^^^^^^^^^^^^^^^^
  File "/home/kayprogrammer/Documents/Projects/Django/bidout-auction-v5/env/lib/python3.11/site-packages/ninja/operation.py", line 202, in _result_to_response
    result = response_model.from_orm(resp_object).dict(
             ^^^^^^^^^^^^^^^^^^^^^^^^^^^^^^^^^^^^
  File "/home/kayprogrammer/Documents/Projects/Django/bidout-auction-v5/env/lib/python3.11/site-packages/ninja/schema.py", line 164, in from_orm
    return super().from_orm(obj)
           ^^^^^^^^^^^^^^^^^^^^^
  File "pydantic/main.py", line 579, in pydantic.main.BaseModel.from_orm
pydantic.error_wrappers.ValidationError: 4 validation errors for NinjaResponseSchema
response -> data -> 0 -> auctioneer
  field required (type=value_error.missing)
response -> data -> 0 -> time_left_seconds
  field required (type=value_error.missing)
response -> data -> 0 -> active
  '>' not supported between instances of 'NoneType' and 'int' (type=type_error)
response -> data -> 0 -> watchlist
  object of type 'bool' has no len() (type=type_error)
2023-07-04 15:44:06,476 django.request ERROR    Internal Server Error: /api/v5/listings/watchlist/
2023-07-04 15:45:07,877 django       ERROR    2 validation errors for NinjaResponseSchema
response -> data -> 0 -> auctioneer
  field required (type=value_error.missing)
response -> data -> 0 -> watchlist
  object of type 'bool' has no len() (type=type_error)
Traceback (most recent call last):
  File "/home/kayprogrammer/Documents/Projects/Django/bidout-auction-v5/env/lib/python3.11/site-packages/ninja/operation.py", line 266, in run
    return self._result_to_response(request, result, temporal_response)
           ^^^^^^^^^^^^^^^^^^^^^^^^^^^^^^^^^^^^^^^^^^^^^^^^^^^^^^^^^^^^
  File "/home/kayprogrammer/Documents/Projects/Django/bidout-auction-v5/env/lib/python3.11/site-packages/ninja/operation.py", line 202, in _result_to_response
    result = response_model.from_orm(resp_object).dict(
             ^^^^^^^^^^^^^^^^^^^^^^^^^^^^^^^^^^^^
  File "/home/kayprogrammer/Documents/Projects/Django/bidout-auction-v5/env/lib/python3.11/site-packages/ninja/schema.py", line 164, in from_orm
    return super().from_orm(obj)
           ^^^^^^^^^^^^^^^^^^^^^
  File "pydantic/main.py", line 579, in pydantic.main.BaseModel.from_orm
pydantic.error_wrappers.ValidationError: 2 validation errors for NinjaResponseSchema
response -> data -> 0 -> auctioneer
  field required (type=value_error.missing)
response -> data -> 0 -> watchlist
  object of type 'bool' has no len() (type=type_error)
2023-07-04 15:45:07,883 django.request ERROR    Internal Server Error: /api/v5/listings/watchlist/
2023-07-04 15:45:57,249 django       ERROR    name 'V' is not defined
Traceback (most recent call last):
  File "/home/kayprogrammer/Documents/Projects/Django/bidout-auction-v5/env/lib/python3.11/site-packages/ninja/operation.py", line 266, in run
    return self._result_to_response(request, result, temporal_response)
           ^^^^^^^^^^^^^^^^^^^^^^^^^^^^^^^^^^^^^^^^^^^^^^^^^^^^^^^^^^^^
  File "/home/kayprogrammer/Documents/Projects/Django/bidout-auction-v5/env/lib/python3.11/site-packages/ninja/operation.py", line 202, in _result_to_response
    result = response_model.from_orm(resp_object).dict(
             ^^^^^^^^^^^^^^^^^^^^^^^^^^^^^^^^^^^^
  File "/home/kayprogrammer/Documents/Projects/Django/bidout-auction-v5/env/lib/python3.11/site-packages/ninja/schema.py", line 164, in from_orm
    return super().from_orm(obj)
           ^^^^^^^^^^^^^^^^^^^^^
  File "pydantic/main.py", line 577, in pydantic.main.BaseModel.from_orm
  File "pydantic/main.py", line 1076, in pydantic.main.validate_model
  File "pydantic/fields.py", line 884, in pydantic.fields.ModelField.validate
  File "pydantic/fields.py", line 1101, in pydantic.fields.ModelField._validate_singleton
  File "pydantic/fields.py", line 1157, in pydantic.fields.ModelField._apply_validators
  File "pydantic/class_validators.py", line 337, in pydantic.class_validators._generic_validator_basic.lambda13
  File "pydantic/main.py", line 711, in pydantic.main.BaseModel.validate
  File "pydantic/main.py", line 339, in pydantic.main.BaseModel.__init__
  File "pydantic/main.py", line 1076, in pydantic.main.validate_model
  File "pydantic/fields.py", line 895, in pydantic.fields.ModelField.validate
  File "pydantic/fields.py", line 928, in pydantic.fields.ModelField._validate_sequence_like
  File "pydantic/fields.py", line 1094, in pydantic.fields.ModelField._validate_singleton
  File "pydantic/fields.py", line 884, in pydantic.fields.ModelField.validate
  File "pydantic/fields.py", line 1101, in pydantic.fields.ModelField._validate_singleton
  File "pydantic/fields.py", line 1157, in pydantic.fields.ModelField._apply_validators
  File "pydantic/class_validators.py", line 337, in pydantic.class_validators._generic_validator_basic.lambda13
  File "pydantic/main.py", line 713, in pydantic.main.BaseModel.validate
  File "pydantic/main.py", line 577, in pydantic.main.BaseModel.from_orm
  File "pydantic/main.py", line 1076, in pydantic.main.validate_model
  File "pydantic/fields.py", line 867, in pydantic.fields.ModelField.validate
  File "pydantic/fields.py", line 1157, in pydantic.fields.ModelField._apply_validators
  File "pydantic/class_validators.py", line 304, in pydantic.class_validators._generic_validator_cls.lambda4
  File "/home/kayprogrammer/Documents/Projects/Django/bidout-auction-v5/apps/listings/schemas.py", line 80, in set_watchlist
    print(type(V))
               ^
NameError: name 'V' is not defined
2023-07-04 15:45:57,256 django.request ERROR    Internal Server Error: /api/v5/listings/
2023-07-04 15:47:37,064 django       ERROR    1 validation error for NinjaResponseSchema
response -> data -> 0 -> auctioneer
  field required (type=value_error.missing)
Traceback (most recent call last):
  File "/home/kayprogrammer/Documents/Projects/Django/bidout-auction-v5/env/lib/python3.11/site-packages/ninja/operation.py", line 266, in run
    return self._result_to_response(request, result, temporal_response)
           ^^^^^^^^^^^^^^^^^^^^^^^^^^^^^^^^^^^^^^^^^^^^^^^^^^^^^^^^^^^^
  File "/home/kayprogrammer/Documents/Projects/Django/bidout-auction-v5/env/lib/python3.11/site-packages/ninja/operation.py", line 202, in _result_to_response
    result = response_model.from_orm(resp_object).dict(
             ^^^^^^^^^^^^^^^^^^^^^^^^^^^^^^^^^^^^
  File "/home/kayprogrammer/Documents/Projects/Django/bidout-auction-v5/env/lib/python3.11/site-packages/ninja/schema.py", line 164, in from_orm
    return super().from_orm(obj)
           ^^^^^^^^^^^^^^^^^^^^^
  File "pydantic/main.py", line 579, in pydantic.main.BaseModel.from_orm
pydantic.error_wrappers.ValidationError: 1 validation error for NinjaResponseSchema
response -> data -> 0 -> auctioneer
  field required (type=value_error.missing)
2023-07-04 15:47:37,073 django.request ERROR    Internal Server Error: /api/v5/listings/watchlist/
2023-07-04 20:23:19,619 django       ERROR    'ASGIRequest' object has no attribute 'auth'
Traceback (most recent call last):
  File "/home/kayprogrammer/Documents/Projects/Django/bidout-auction-v5/env/lib/python3.11/site-packages/ninja/operation.py", line 265, in run
    result = await self.view_func(request, **values)
             ^^^^^^^^^^^^^^^^^^^^^^^^^^^^^^^^^^^^^^^
  File "/home/kayprogrammer/Documents/Projects/Django/bidout-auction-v5/apps/listings/views.py", line 181, in retrieve_category_listings
    client = await request.auth
                   ^^^^^^^^^^^^
AttributeError: 'ASGIRequest' object has no attribute 'auth'
2023-07-04 20:23:19,695 django.request ERROR    Internal Server Error: /api/v5/listings/categories/asas/
2023-07-04 20:24:02,326 django.request WARNING  Not Found: /api/v5/listings/categories/aaa/
2023-07-04 20:24:09,352 django.request WARNING  Not Found: /api/v5/listings/categories/Accessories/
2023-07-04 20:24:14,886 django       ERROR    Object of type Listing is not JSON serializable
Traceback (most recent call last):
  File "/home/kayprogrammer/Documents/Projects/Django/bidout-auction-v5/env/lib/python3.11/site-packages/ninja/operation.py", line 266, in run
    return self._result_to_response(request, result, temporal_response)
           ^^^^^^^^^^^^^^^^^^^^^^^^^^^^^^^^^^^^^^^^^^^^^^^^^^^^^^^^^^^^
  File "/home/kayprogrammer/Documents/Projects/Django/bidout-auction-v5/env/lib/python3.11/site-packages/ninja/operation.py", line 192, in _result_to_response
    return self.api.create_response(
           ^^^^^^^^^^^^^^^^^^^^^^^^^
  File "/home/kayprogrammer/Documents/Projects/Django/bidout-auction-v5/env/lib/python3.11/site-packages/ninja/main.py", line 416, in create_response
    content = self.renderer.render(request, data, response_status=status)
              ^^^^^^^^^^^^^^^^^^^^^^^^^^^^^^^^^^^^^^^^^^^^^^^^^^^^^^^^^^^
  File "/home/kayprogrammer/Documents/Projects/Django/bidout-auction-v5/env/lib/python3.11/site-packages/ninja/renderers.py", line 25, in render
    return json.dumps(data, cls=self.encoder_class, **self.json_dumps_params)
           ^^^^^^^^^^^^^^^^^^^^^^^^^^^^^^^^^^^^^^^^^^^^^^^^^^^^^^^^^^^^^^^^^^
  File "/usr/lib/python3.11/json/__init__.py", line 238, in dumps
    **kw).encode(obj)
          ^^^^^^^^^^^
  File "/usr/lib/python3.11/json/encoder.py", line 200, in encode
    chunks = self.iterencode(o, _one_shot=True)
             ^^^^^^^^^^^^^^^^^^^^^^^^^^^^^^^^^^
  File "/usr/lib/python3.11/json/encoder.py", line 258, in iterencode
    return _iterencode(o, 0)
           ^^^^^^^^^^^^^^^^^
  File "/home/kayprogrammer/Documents/Projects/Django/bidout-auction-v5/env/lib/python3.11/site-packages/ninja/responses.py", line 25, in default
    return super().default(o)
           ^^^^^^^^^^^^^^^^^^
  File "/home/kayprogrammer/Documents/Projects/Django/bidout-auction-v5/env/lib/python3.11/site-packages/django/core/serializers/json.py", line 106, in default
    return super().default(o)
           ^^^^^^^^^^^^^^^^^^
  File "/usr/lib/python3.11/json/encoder.py", line 180, in default
    raise TypeError(f'Object of type {o.__class__.__name__} '
TypeError: Object of type Listing is not JSON serializable
2023-07-04 20:24:15,437 django.request ERROR    Internal Server Error: /api/v5/listings/categories/accessories/
2023-07-04 20:26:00,030 django.request WARNING  Not Found: /api/v5/listings/categories/technology/
2023-07-04 20:26:12,167 django.request WARNING  Not Found: /api/v1/creators
2023-07-04 20:26:13,210 django.request WARNING  Not Found: /api/v1/creators
2023-07-04 20:26:28,333 django.request WARNING  Not Found: /api/v5/listings/categories/technology/
2023-07-04 20:28:46,515 django       ERROR    'NoneType' object has no attribute 'id'
Traceback (most recent call last):
  File "/home/kayprogrammer/Documents/Projects/Django/bidout-auction-v5/env/lib/python3.11/site-packages/ninja/operation.py", line 265, in run
    result = await self.view_func(request, **values)
             ^^^^^^^^^^^^^^^^^^^^^^^^^^^^^^^^^^^^^^^
  File "/home/kayprogrammer/Documents/Projects/Django/bidout-auction-v5/apps/listings/views.py", line 193, in retrieve_category_listings
    Listing.objects.filter(category_id=category.id)
                                       ^^^^^^^^^^^
AttributeError: 'NoneType' object has no attribute 'id'
2023-07-04 20:28:46,554 django.request ERROR    Internal Server Error: /api/v5/listings/categories/other/
